Workbook

Sheet РАСХОДЫ
A1: ПАРАМЕТРЫ
A2: Число участников | C2: 70
A3: Доля FULL билетов | C3: 0.6
A4: Плательщик USt (НДС) | C4: Да
A6: # | B6: Категория | C6: Статья | D6: Ед. | E6: Low (unit) | F6: Mid (unit) | G6: High (unit) | H6: Low (total) | I6: Mid (total) | J6: High (total) | K6: Привязка
A7: 1 | B7: Venue | C7: Аренда Дни 1–2 (зал + breakout + Demo Zone) | D7: 2 дня | E7: 8000 | F7: 13000 | G7: 18000 | H7: =IF('РАСХОДЫ'!$C$2<=60,E7*0.85,IF('РАСХОДЫ'!$C$2<=85,E7,E7*1.15)) | I7: =IF('РАСХОДЫ'!$C$2<=60,F7*0.85,IF('РАСХОДЫ'!$C$2<=85,F7,F7*1.15)) | J7: =IF('РАСХОДЫ'!$C$2<=60,G7*0.85,IF('РАСХОДЫ'!$C$2<=85,G7,G7*1.15)) | K7: ≤60×0.85, >60×1.0, >85×1.15
A8: 2 | B8: Venue | C8: Аренда День 3 (утренняя сессия, без breakout) | D8: 1 день | E8: 2000 | F8: 3500 | G8: 5000 | H8: =E8 | I8: =F8 | J8: =G8 | K8: Фикс.
A9: 3 | B9: Кейтеринг | C9: Кофе-брейки + обеды, Дни 1–2 | D9: чел/день | E9: 35 | F9: 55 | G9: 75 | H9: =E9*'РАСХОДЫ'!$C$2*2 | I9: =F9*'РАСХОДЫ'!$C$2*2 | J9: =G9*'РАСХОДЫ'!$C$2*2 | K9: × участников × 2 дня
A10: 4 | B10: Кейтеринг | C10: Кофе + лёгкий обед, День 3 | D10: чел | E10: 20 | F10: 30 | G10: 40 | H10: =E10*ROUND('РАСХОДЫ'!$C$2*'РАСХОДЫ'!$C$3,0) | I10: =F10*ROUND('РАСХОДЫ'!$C$2*'РАСХОДЫ'!$C$3,0) | J10: =G10*ROUND('РАСХОДЫ'!$C$2*'РАСХОДЫ'!$C$3,0) | K10: × участников FULL
A11: 5 | B11: Ужины | C11: Групповой ужин #1 (чт, рядом с Alizée) | D11: чел | E11: 60 | F11: 90 | G11: 130 | H11: =E11*ROUND('РАСХОДЫ'!$C$2*'РАСХОДЫ'!$C$3,0) | I11: =F11*ROUND('РАСХОДЫ'!$C$2*'РАСХОДЫ'!$C$3,0) | J11: =G11*ROUND('РАСХОДЫ'!$C$2*'РАСХОДЫ'!$C$3,0) | K11: × участников FULL
A12: 6 | B12: Ужины | C12: Групповой ужин #2 (пт, рядом с Palast) | D12: чел | E12: 60 | F12: 90 | G12: 130 | H12: =E12*ROUND('РАСХОДЫ'!$C$2*'РАСХОДЫ'!$C$3,0) | I12: =F12*ROUND('РАСХОДЫ'!$C$2*'РАСХОДЫ'!$C$3,0) | J12: =G12*ROUND('РАСХОДЫ'!$C$2*'РАСХОДЫ'!$C$3,0) | K12: × участников FULL
A13: 7 | B13: Шоу | C13: Билеты Alizée (групповая скидка) | D13: чел | E13: 53 | F13: 75 | G13: 94 | H13: =E13*ROUND('РАСХОДЫ'!$C$2*'РАСХОДЫ'!$C$3,0) | I13: =F13*ROUND('РАСХОДЫ'!$C$2*'РАСХОДЫ'!$C$3,0) | J13: =G13*ROUND('РАСХОДЫ'!$C$2*'РАСХОДЫ'!$C$3,0) | K13: × участников FULL
A14: 8 | B14: Шоу | C14: Билеты Friedrichstadt-Palast | D14: чел | E14: 40 | F14: 60 | G14: 80 | H14: =E14*ROUND('РАСХОДЫ'!$C$2*'РАСХОДЫ'!$C$3,0) | I14: =F14*ROUND('РАСХОДЫ'!$C$2*'РАСХОДЫ'!$C$3,0) | J14: =G14*ROUND('РАСХОДЫ'!$C$2*'РАСХОДЫ'!$C$3,0) | K14: × участников FULL
A15: 9 | B15: AV | C15: Оборудование + техник (2 дня) | D15: комплект | E15: 2500 | F15: 5000 | G15: 8000 | H15: =E15 | I15: =F15 | J15: =G15 | K15: Фикс.
A16: 10 | B16: Фасилитаторы | C16: Главный ведущий (2 дня + подготовка) | D16: чел | E16: 3000 | F16: 5000 | G16: 8000 | H16: =E16 | I16: =F16 | J16: =G16 | K16: Фикс.
A17: 11 | B17: Фасилитаторы | C17: Breakout-фасилитаторы (5–6, День 2) | D17: день | E17: 5000 | F17: 8000 | G17: 12000 | H17: =IF('РАСХОДЫ'!$C$2<=50,E17,IF('РАСХОДЫ'!$C$2<=75,E17*1.2,E17*1.4)) | I17: =IF('РАСХОДЫ'!$C$2<=50,F17,IF('РАСХОДЫ'!$C$2<=75,F17*1.2,F17*1.4)) | J17: =IF('РАСХОДЫ'!$C$2<=50,G17,IF('РАСХОДЫ'!$C$2<=75,G17*1.2,G17*1.4)) | K17: Число групп зависит от участников
A18: 12 | B18: Фото/видео | C18: Фотограф (2 дня) | D18: комплект | E18: 1800 | F18: 2500 | G18: 4000 | H18: =E18 | I18: =F18 | J18: =G18 | K18: Фикс.
A19: 13 | B19: Фото/видео | C19: Видеограф + монтаж | D19: комплект | E19: 2000 | F19: 4000 | G19: 7000 | H19: =E19 | I19: =F19 | J19: =G19 | K19: Фикс.
A20: 14 | B20: Печать | C20: Бейджи, карточки, баннеры, материалы | D20: комплект | E20: 1500 | F20: 2500 | G20: 4000 | H20: =E20*0.7+E20*0.3*'РАСХОДЫ'!$C$2/70 | I20: =F20*0.7+F20*0.3*'РАСХОДЫ'!$C$2/70 | J20: =G20*0.7+G20*0.3*'РАСХОДЫ'!$C$2/70 | K20: Частично лин. (бейджи/карточки)
A21: 15 | B21: Транспорт | C21: Автобус(ы) трансферы, 2 вечера | D21: комплект | E21: 1500 | F21: 3000 | G21: 5000 | H21: =IF('РАСХОДЫ'!$C$2<=50,E21,E21*2) | I21: =IF('РАСХОДЫ'!$C$2<=50,F21,F21*2) | J21: =IF('РАСХОДЫ'!$C$2<=50,G21,G21*2) | K21: 1 бус ≤50, 2 буса >50
A22: 16 | B22: Страховка | C22: Ответственность + отмена | D22: комплект | E22: 200 | F22: 500 | G22: 1000 | H22: =E22 | I22: =F22 | J22: =G22 | K22: Фикс.
A23: 17 | B23: Сайт/маркетинг | C23: Лендинг, рассылки, LinkedIn, дизайн | D23: комплект | E23: 1500 | F23: 3000 | G23: 5000 | H23: =E23 | I23: =F23 | J23: =G23 | K23: Фикс.
A24: 18 | B24: Команда орг. | C24: Перелёты + проживание команды (3–4 чел, 4–5 ночей) | D24: комплект | E24: 3000 | F24: 5000 | G24: 8000 | H24: =E24 | I24: =F24 | J24: =G24 | K24: Фикс.
A25: 19 | B25: Тикетинг | C25: Комиссия платформы (Eventbrite/Stripe) | D25: % от выручки | E25: 0.03 | F25: 0.04 | G25: 0.05 | H25: =E25*'ДОХОДЫ'!$E$30 | I25: =F25*'ДОХОДЫ'!$E$30 | J25: =G25*'ДОХОДЫ'!$E$30 | K25: % от общей выручки с билетов
A26: 20 | B26: Юрист/бух | C26: Контракты, GDPR, налоговый учёт | D26: комплект | E26: 1000 | F26: 2000 | G26: 3500 | H26: =E26 | I26: =F26 | J26: =G26 | K26: Фикс.
C27: Промежуточный итог (стр. 1–20) | H27: =SUM(H7:H26) | I27: =SUM(I7:I26) | J27: =SUM(J7:J26)
A28: 21 | B28: НДС (USt) | C28: 19% на расходы (если не плательщик USt) | D28: % | E28: 0.19 | F28: 0.19 | G28: 0.19 | H28: =IF($C$4="Да",0,H27*0.15) | I28: =IF($C$4="Да",0,I27*0.15) | J28: =IF($C$4="Да",0,J27*0.15) | K28: Если плательщик USt — Vorsteuer вычитается, строка = 0
A29: 22 | B29: Прочее | C29: Непредвиденные расходы | D29: % | E29: 0.08 | F29: 0.1 | G29: 0.12 | H29: =E29*H27 | I29: =F29*I27 | J29: =G29*J27 | K29: % от суммы строк 1–20
C31: ИТОГО РАСХОДЫ | H31: =H27+H28+H29 | I31: =I27+I28+I29 | J31: =J27+J28+J29
A33: Примечание по НДС: Если EVERSEE — плательщик USt, расходы netto, доходы netto, строка НДС = 0. Если нет — НДС ~15% от суммы расходов.

Sheet ДОХОДЫ
A1: ПАРАМЕТРЫ ДОХОДОВ
A2: Доля Creative / Tech | C2: 0.6 | E2: 60% Creative, 40% Tech
A3: Доля Early Bird | C3: 0.5
A4: Доля FULL vs FORUM | C4: ='РАСХОДЫ'!$C$3 | E4: Связана с РАСХОДЫ!C3
A5: Слоты Lightning Talk (продано) | C5: 8 | E5: из 12
A6: Слоты Keynote (продано) | C6: 1 | E6: из 2
A7: Partner пакетов | C7: 1 | E7: вкл. 2 билета TECH FULL
A8: Strategic Partner пакетов | C8: 1 | E8: вкл. 4 билета TECH FULL
A9: Title Partner пакетов | C9: 0 | E9: вкл. 6 билетов TECH FULL
A10: Билеты из пакетов (TECH FULL) | C10: =$C$7*2+$C$8*4+$C$9*6 | E10: Вычитаются из платных TECH билетов
A12: ДОХОДЫ ОТ БИЛЕТОВ И ПАРТНЁРОВ
A13: Источник | B13: Кол-во (расчёт) | C13: Цена Early Bird | D13: Цена Regular (+30%) | E13: Итого
A14: CREATIVE FORUM | B14: =ROUND('РАСХОДЫ'!$C$2*$C$2*(1-$C$4),0) | C14: 290 | D14: 377 | E14: =B14*($C$3*C14+(1-$C$3)*D14)
A15: CREATIVE FULL | B15: =ROUND('РАСХОДЫ'!$C$2*$C$2*$C$4,0) | C15: 590 | D15: 767 | E15: =B15*($C$3*C15+(1-$C$3)*D15)
A16: TECH FORUM | B16: =MAX(ROUND('РАСХОДЫ'!$C$2*(1-$C$2)*(1-$C$4),0)-0,0) | C16: 490 | D16: 637 | E16: =B16*($C$3*C16+(1-$C$3)*D16)
A17: TECH FULL | B17: =MAX(ROUND('РАСХОДЫ'!$C$2*(1-$C$2)*$C$4,0)-$C$10,0) | C17: 890 | D17: 1157 | E17: =B17*($C$3*C17+(1-$C$3)*D17)
A19: СЛОТЫ ВЫСТУПЛЕНИЙ
A20: Lightning Talk | B20: =$C$5 | C20: 500 | E20: =B20*C20
A21: Keynote | B21: =$C$6 | C21: 1500 | E21: =B21*C21
A23: ПАРТНЁРСКИЕ ПАКЕТЫ
A24: Partner | B24: =$C$7 | C24: 3000 | E24: =B24*C24
A25: Strategic Partner | B25: =$C$8 | C25: 8000 | E25: =B25*C25
A26: Title Partner | B26: =$C$9 | C26: 15000 | E26: =B26*C26
A28: ИТОГО ДОХОДЫ | E28: =E14+E15+E16+E17+E20+E21+E24+E25+E26
A30: Выручка (ссылка для расчётов) | E30: =E28

Sheet АНАЛИЗ
A1: СВОДКА БАЗОВОГО СЦЕНАРИЯ (Mid)
A3: Итого расходы (Mid) | B3: ='РАСХОДЫ'!I31
A4: Итого доходы | B4: ='ДОХОДЫ'!E30
A5: Комиссия тикетинга (Mid) | B5: ='РАСХОДЫ'!I25
A6: Чистый результат | B6: =B4-B3
A7: Маржа | B7: =IF(B4=0,0,B6/B4)
A10: BREAK-EVEN АНАЛИЗ
A11: Участников | B11: Расходы (Mid) | C11: Доходы | D11: Результат | E11: Маржа
A12: 30 | B12: =((IF(30<=60,13000*0.85,IF(30<=85,13000,13000*1.15)))+3500+55*30*2+30*ROUND(30*'РАСХОДЫ'!$C$3,0)+90*ROUND(30*'РАСХОДЫ'!$C$3,0)+90*ROUND(30*'РАСХОДЫ'!$C$3,0)+75*ROUND(30*'РАСХОДЫ'!$C$3,0)+60*ROUND(30*'РАСХОДЫ'!$C$3,0)+5000+5000+(IF(30<=50,8000,IF(30<=75,8000*1.2,8000*1.4)))+2500+4000+(2500*0.7+2500*0.3*30/70)+(IF(30<=50,3000,3000*2))+500+3000+5000+2000)+(IF('РАСХОДЫ'!$C$4="Да",0,((IF(30<=60,13000*0.85,IF(30<=85,13000,13000*1.15)))+3500+55*30*2+30*ROUND(30*'РАСХОДЫ'!$C$3,0)+90*ROUND(30*'РАСХОДЫ'!$C$3,0)+90*ROUND(30*'РАСХОДЫ'!$C$3,0)+75*ROUND(30*'РАСХОДЫ'!$C$3,0)+60*ROUND(30*'РАСХОДЫ'!$C$3,0)+5000+5000+(IF(30<=50,8000,IF(30<=75,8000*1.2,8000*1.4)))+2500+4000+(2500*0.7+2500*0.3*30/70)+(IF(30<=50,3000,3000*2))+500+3000+5000+2000)*0.15))+(((IF(30<=60,13000*0.85,IF(30<=85,13000,13000*1.15)))+3500+55*30*2+30*ROUND(30*'РАСХОДЫ'!$C$3,0)+90*ROUND(30*'РАСХОДЫ'!$C$3,0)+90*ROUND(30*'РАСХОДЫ'!$C$3,0)+75*ROUND(30*'РАСХОДЫ'!$C$3,0)+60*ROUND(30*'РАСХОДЫ'!$C$3,0)+5000+5000+(IF(30<=50,8000,IF(30<=75,8000*1.2,8000*1.4)))+2500+4000+(2500*0.7+2500*0.3*30/70)+(IF(30<=50,3000,3000*2))+500+3000+5000+2000)*0.1)+0.04*((ROUND(30*'ДОХОДЫ'!$C$2*(1-'РАСХОДЫ'!$C$3),0))*('ДОХОДЫ'!$C$3*290+(1-'ДОХОДЫ'!$C$3)*377)+(ROUND(30*'ДОХОДЫ'!$C$2*'РАСХОДЫ'!$C$3,0))*('ДОХОДЫ'!$C$3*590+(1-'ДОХОДЫ'!$C$3)*767)+(MAX(ROUND(30*(1-'ДОХОДЫ'!$C$2)*(1-'РАСХОДЫ'!$C$3),0),0))*('ДОХОДЫ'!$C$3*490+(1-'ДОХОДЫ'!$C$3)*637)+(MAX(ROUND(30*(1-'ДОХОДЫ'!$C$2)*'РАСХОДЫ'!$C$3,0)-'ДОХОДЫ'!$C$10,0))*('ДОХОДЫ'!$C$3*890+(1-'ДОХОДЫ'!$C$3)*1157)+'ДОХОДЫ'!$C$5*500+'ДОХОДЫ'!$C$6*1500+'ДОХОДЫ'!$C$7*3000+'ДОХОДЫ'!$C$8*8000+'ДОХОДЫ'!$C$9*15000) | C12: =(ROUND(30*'ДОХОДЫ'!$C$2*(1-'РАСХОДЫ'!$C$3),0))*('ДОХОДЫ'!$C$3*290+(1-'ДОХОДЫ'!$C$3)*377)+(ROUND(30*'ДОХОДЫ'!$C$2*'РАСХОДЫ'!$C$3,0))*('ДОХОДЫ'!$C$3*590+(1-'ДОХОДЫ'!$C$3)*767)+(MAX(ROUND(30*(1-'ДОХОДЫ'!$C$2)*(1-'РАСХОДЫ'!$C$3),0),0))*('ДОХОДЫ'!$C$3*490+(1-'ДОХОДЫ'!$C$3)*637)+(MAX(ROUND(30*(1-'ДОХОДЫ'!$C$2)*'РАСХОДЫ'!$C$3,0)-'ДОХОДЫ'!$C$10,0))*('ДОХОДЫ'!$C$3*890+(1-'ДОХОДЫ'!$C$3)*1157)+'ДОХОДЫ'!$C$5*500+'ДОХОДЫ'!$C$6*1500+'ДОХОДЫ'!$C$7*3000+'ДОХОДЫ'!$C$8*8000+'ДОХОДЫ'!$C$9*15000 | D12: =C12-B12 | E12: =IF(C12=0,0,D12/C12)
A13: 35 | B13: =((IF(35<=60,13000*0.85,IF(35<=85,13000,13000*1.15)))+3500+55*35*2+30*ROUND(35*'РАСХОДЫ'!$C$3,0)+90*ROUND(35*'РАСХОДЫ'!$C$3,0)+90*ROUND(35*'РАСХОДЫ'!$C$3,0)+75*ROUND(35*'РАСХОДЫ'!$C$3,0)+60*ROUND(35*'РАСХОДЫ'!$C$3,0)+5000+5000+(IF(35<=50,8000,IF(35<=75,8000*1.2,8000*1.4)))+2500+4000+(2500*0.7+2500*0.3*35/70)+(IF(35<=50,3000,3000*2))+500+3000+5000+2000)+(IF('РАСХОДЫ'!$C$4="Да",0,((IF(35<=60,13000*0.85,IF(35<=85,13000,13000*1.15)))+3500+55*35*2+30*ROUND(35*'РАСХОДЫ'!$C$3,0)+90*ROUND(35*'РАСХОДЫ'!$C$3,0)+90*ROUND(35*'РАСХОДЫ'!$C$3,0)+75*ROUND(35*'РАСХОДЫ'!$C$3,0)+60*ROUND(35*'РАСХОДЫ'!$C$3,0)+5000+5000+(IF(35<=50,8000,IF(35<=75,8000*1.2,8000*1.4)))+2500+4000+(2500*0.7+2500*0.3*35/70)+(IF(35<=50,3000,3000*2))+500+3000+5000+2000)*0.15))+(((IF(35<=60,13000*0.85,IF(35<=85,13000,13000*1.15)))+3500+55*35*2+30*ROUND(35*'РАСХОДЫ'!$C$3,0)+90*ROUND(35*'РАСХОДЫ'!$C$3,0)+90*ROUND(35*'РАСХОДЫ'!$C$3,0)+75*ROUND(35*'РАСХОДЫ'!$C$3,0)+60*ROUND(35*'РАСХОДЫ'!$C$3,0)+5000+5000+(IF(35<=50,8000,IF(35<=75,8000*1.2,8000*1.4)))+2500+4000+(2500*0.7+2500*0.3*35/70)+(IF(35<=50,3000,3000*2))+500+3000+5000+2000)*0.1)+0.04*((ROUND(35*'ДОХОДЫ'!$C$2*(1-'РАСХОДЫ'!$C$3),0))*('ДОХОДЫ'!$C$3*290+(1-'ДОХОДЫ'!$C$3)*377)+(ROUND(35*'ДОХОДЫ'!$C$2*'РАСХОДЫ'!$C$3,0))*('ДОХОДЫ'!$C$3*590+(1-'ДОХОДЫ'!$C$3)*767)+(MAX(ROUND(35*(1-'ДОХОДЫ'!$C$2)*(1-'РАСХОДЫ'!$C$3),0),0))*('ДОХОДЫ'!$C$3*490+(1-'ДОХОДЫ'!$C$3)*637)+(MAX(ROUND(35*(1-'ДОХОДЫ'!$C$2)*'РАСХОДЫ'!$C$3,0)-'ДОХОДЫ'!$C$10,0))*('ДОХОДЫ'!$C$3*890+(1-'ДОХОДЫ'!$C$3)*1157)+'ДОХОДЫ'!$C$5*500+'ДОХОДЫ'!$C$6*1500+'ДОХОДЫ'!$C$7*3000+'ДОХОДЫ'!$C$8*8000+'ДОХОДЫ'!$C$9*15000) | C13: =(ROUND(35*'ДОХОДЫ'!$C$2*(1-'РАСХОДЫ'!$C$3),0))*('ДОХОДЫ'!$C$3*290+(1-'ДОХОДЫ'!$C$3)*377)+(ROUND(35*'ДОХОДЫ'!$C$2*'РАСХОДЫ'!$C$3,0))*('ДОХОДЫ'!$C$3*590+(1-'ДОХОДЫ'!$C$3)*767)+(MAX(ROUND(35*(1-'ДОХОДЫ'!$C$2)*(1-'РАСХОДЫ'!$C$3),0),0))*('ДОХОДЫ'!$C$3*490+(1-'ДОХОДЫ'!$C$3)*637)+(MAX(ROUND(35*(1-'ДОХОДЫ'!$C$2)*'РАСХОДЫ'!$C$3,0)-'ДОХОДЫ'!$C$10,0))*('ДОХОДЫ'!$C$3*890+(1-'ДОХОДЫ'!$C$3)*1157)+'ДОХОДЫ'!$C$5*500+'ДОХОДЫ'!$C$6*1500+'ДОХОДЫ'!$C$7*3000+'ДОХОДЫ'!$C$8*8000+'ДОХОДЫ'!$C$9*15000 | D13: =C13-B13 | E13: =IF(C13=0,0,D13/C13)
A14: 40 | B14: =((IF(40<=60,13000*0.85,IF(40<=85,13000,13000*1.15)))+3500+55*40*2+30*ROUND(40*'РАСХОДЫ'!$C$3,0)+90*ROUND(40*'РАСХОДЫ'!$C$3,0)+90*ROUND(40*'РАСХОДЫ'!$C$3,0)+75*ROUND(40*'РАСХОДЫ'!$C$3,0)+60*ROUND(40*'РАСХОДЫ'!$C$3,0)+5000+5000+(IF(40<=50,8000,IF(40<=75,8000*1.2,8000*1.4)))+2500+4000+(2500*0.7+2500*0.3*40/70)+(IF(40<=50,3000,3000*2))+500+3000+5000+2000)+(IF('РАСХОДЫ'!$C$4="Да",0,((IF(40<=60,13000*0.85,IF(40<=85,13000,13000*1.15)))+3500+55*40*2+30*ROUND(40*'РАСХОДЫ'!$C$3,0)+90*ROUND(40*'РАСХОДЫ'!$C$3,0)+90*ROUND(40*'РАСХОДЫ'!$C$3,0)+75*ROUND(40*'РАСХОДЫ'!$C$3,0)+60*ROUND(40*'РАСХОДЫ'!$C$3,0)+5000+5000+(IF(40<=50,8000,IF(40<=75,8000*1.2,8000*1.4)))+2500+4000+(2500*0.7+2500*0.3*40/70)+(IF(40<=50,3000,3000*2))+500+3000+5000+2000)*0.15))+(((IF(40<=60,13000*0.85,IF(40<=85,13000,13000*1.15)))+3500+55*40*2+30*ROUND(40*'РАСХОДЫ'!$C$3,0)+90*ROUND(40*'РАСХОДЫ'!$C$3,0)+90*ROUND(40*'РАСХОДЫ'!$C$3,0)+75*ROUND(40*'РАСХОДЫ'!$C$3,0)+60*ROUND(40*'РАСХОДЫ'!$C$3,0)+5000+5000+(IF(40<=50,8000,IF(40<=75,8000*1.2,8000*1.4)))+2500+4000+(2500*0.7+2500*0.3*40/70)+(IF(40<=50,3000,3000*2))+500+3000+5000+2000)*0.1)+0.04*((ROUND(40*'ДОХОДЫ'!$C$2*(1-'РАСХОДЫ'!$C$3),0))*('ДОХОДЫ'!$C$3*290+(1-'ДОХОДЫ'!$C$3)*377)+(ROUND(40*'ДОХОДЫ'!$C$2*'РАСХОДЫ'!$C$3,0))*('ДОХОДЫ'!$C$3*590+(1-'ДОХОДЫ'!$C$3)*767)+(MAX(ROUND(40*(1-'ДОХОДЫ'!$C$2)*(1-'РАСХОДЫ'!$C$3),0),0))*('ДОХОДЫ'!$C$3*490+(1-'ДОХОДЫ'!$C$3)*637)+(MAX(ROUND(40*(1-'ДОХОДЫ'!$C$2)*'РАСХОДЫ'!$C$3,0)-'ДОХОДЫ'!$C$10,0))*('ДОХОДЫ'!$C$3*890+(1-'ДОХОДЫ'!$C$3)*1157)+'ДОХОДЫ'!$C$5*500+'ДОХОДЫ'!$C$6*1500+'ДОХОДЫ'!$C$7*3000+'ДОХОДЫ'!$C$8*8000+'ДОХОДЫ'!$C$9*15000) | C14: =(ROUND(40*'ДОХОДЫ'!$C$2*(1-'РАСХОДЫ'!$C$3),0))*('ДОХОДЫ'!$C$3*290+(1-'ДОХОДЫ'!$C$3)*377)+(ROUND(40*'ДОХОДЫ'!$C$2*'РАСХОДЫ'!$C$3,0))*('ДОХОДЫ'!$C$3*590+(1-'ДОХОДЫ'!$C$3)*767)+(MAX(ROUND(40*(1-'ДОХОДЫ'!$C$2)*(1-'РАСХОДЫ'!$C$3),0),0))*('ДОХОДЫ'!$C$3*490+(1-'ДОХОДЫ'!$C$3)*637)+(MAX(ROUND(40*(1-'ДОХОДЫ'!$C$2)*'РАСХОДЫ'!$C$3,0)-'ДОХОДЫ'!$C$10,0))*('ДОХОДЫ'!$C$3*890+(1-'ДОХОДЫ'!$C$3)*1157)+'ДОХОДЫ'!$C$5*500+'ДОХОДЫ'!$C$6*1500+'ДОХОДЫ'!$C$7*3000+'ДОХОДЫ'!$C$8*8000+'ДОХОДЫ'!$C$9*15000 | D14: =C14-B14 | E14: =IF(C14=0,0,D14/C14)
A15: 45 | B15: =((IF(45<=60,13000*0.85,IF(45<=85,13000,13000*1.15)))+3500+55*45*2+30*ROUND(45*'РАСХОДЫ'!$C$3,0)+90*ROUND(45*'РАСХОДЫ'!$C$3,0)+90*ROUND(45*'РАСХОДЫ'!$C$3,0)+75*ROUND(45*'РАСХОДЫ'!$C$3,0)+60*ROUND(45*'РАСХОДЫ'!$C$3,0)+5000+5000+(IF(45<=50,8000,IF(45<=75,8000*1.2,8000*1.4)))+2500+4000+(2500*0.7+2500*0.3*45/70)+(IF(45<=50,3000,3000*2))+500+3000+5000+2000)+(IF('РАСХОДЫ'!$C$4="Да",0,((IF(45<=60,13000*0.85,IF(45<=85,13000,13000*1.15)))+3500+55*45*2+30*ROUND(45*'РАСХОДЫ'!$C$3,0)+90*ROUND(45*'РАСХОДЫ'!$C$3,0)+90*ROUND(45*'РАСХОДЫ'!$C$3,0)+75*ROUND(45*'РАСХОДЫ'!$C$3,0)+60*ROUND(45*'РАСХОДЫ'!$C$3,0)+5000+5000+(IF(45<=50,8000,IF(45<=75,8000*1.2,8000*1.4)))+2500+4000+(2500*0.7+2500*0.3*45/70)+(IF(45<=50,3000,3000*2))+500+3000+5000+2000)*0.15))+(((IF(45<=60,13000*0.85,IF(45<=85,13000,13000*1.15)))+3500+55*45*2+30*ROUND(45*'РАСХОДЫ'!$C$3,0)+90*ROUND(45*'РАСХОДЫ'!$C$3,0)+90*ROUND(45*'РАСХОДЫ'!$C$3,0)+75*ROUND(45*'РАСХОДЫ'!$C$3,0)+60*ROUND(45*'РАСХОДЫ'!$C$3,0)+5000+5000+(IF(45<=50,8000,IF(45<=75,8000*1.2,8000*1.4)))+2500+4000+(2500*0.7+2500*0.3*45/70)+(IF(45<=50,3000,3000*2))+500+3000+5000+2000)*0.1)+0.04*((ROUND(45*'ДОХОДЫ'!$C$2*(1-'РАСХОДЫ'!$C$3),0))*('ДОХОДЫ'!$C$3*290+(1-'ДОХОДЫ'!$C$3)*377)+(ROUND(45*'ДОХОДЫ'!$C$2*'РАСХОДЫ'!$C$3,0))*('ДОХОДЫ'!$C$3*590+(1-'ДОХОДЫ'!$C$3)*767)+(MAX(ROUND(45*(1-'ДОХОДЫ'!$C$2)*(1-'РАСХОДЫ'!$C$3),0),0))*('ДОХОДЫ'!$C$3*490+(1-'ДОХОДЫ'!$C$3)*637)+(MAX(ROUND(45*(1-'ДОХОДЫ'!$C$2)*'РАСХОДЫ'!$C$3,0)-'ДОХОДЫ'!$C$10,0))*('ДОХОДЫ'!$C$3*890+(1-'ДОХОДЫ'!$C$3)*1157)+'ДОХОДЫ'!$C$5*500+'ДОХОДЫ'!$C$6*1500+'ДОХОДЫ'!$C$7*3000+'ДОХОДЫ'!$C$8*8000+'ДОХОДЫ'!$C$9*15000) | C15: =(ROUND(45*'ДОХОДЫ'!$C$2*(1-'РАСХОДЫ'!$C$3),0))*('ДОХОДЫ'!$C$3*290+(1-'ДОХОДЫ'!$C$3)*377)+(ROUND(45*'ДОХОДЫ'!$C$2*'РАСХОДЫ'!$C$3,0))*('ДОХОДЫ'!$C$3*590+(1-'ДОХОДЫ'!$C$3)*767)+(MAX(ROUND(45*(1-'ДОХОДЫ'!$C$2)*(1-'РАСХОДЫ'!$C$3),0),0))*('ДОХОДЫ'!$C$3*490+(1-'ДОХОДЫ'!$C$3)*637)+(MAX(ROUND(45*(1-'ДОХОДЫ'!$C$2)*'РАСХОДЫ'!$C$3,0)-'ДОХОДЫ'!$C$10,0))*('ДОХОДЫ'!$C$3*890+(1-'ДОХОДЫ'!$C$3)*1157)+'ДОХОДЫ'!$C$5*500+'ДОХОДЫ'!$C$6*1500+'ДОХОДЫ'!$C$7*3000+'ДОХОДЫ'!$C$8*8000+'ДОХОДЫ'!$C$9*15000 | D15: =C15-B15 | E15: =IF(C15=0,0,D15/C15)
A16: 50 | B16: =((IF(50<=60,13000*0.85,IF(50<=85,13000,13000*1.15)))+3500+55*50*2+30*ROUND(50*'РАСХОДЫ'!$C$3,0)+90*ROUND(50*'РАСХОДЫ'!$C$3,0)+90*ROUND(50*'РАСХОДЫ'!$C$3,0)+75*ROUND(50*'РАСХОДЫ'!$C$3,0)+60*ROUND(50*'РАСХОДЫ'!$C$3,0)+5000+5000+(IF(50<=50,8000,IF(50<=75,8000*1.2,8000*1.4)))+2500+4000+(2500*0.7+2500*0.3*50/70)+(IF(50<=50,3000,3000*2))+500+3000+5000+2000)+(IF('РАСХОДЫ'!$C$4="Да",0,((IF(50<=60,13000*0.85,IF(50<=85,13000,13000*1.15)))+3500+55*50*2+30*ROUND(50*'РАСХОДЫ'!$C$3,0)+90*ROUND(50*'РАСХОДЫ'!$C$3,0)+90*ROUND(50*'РАСХОДЫ'!$C$3,0)+75*ROUND(50*'РАСХОДЫ'!$C$3,0)+60*ROUND(50*'РАСХОДЫ'!$C$3,0)+5000+5000+(IF(50<=50,8000,IF(50<=75,8000*1.2,8000*1.4)))+2500+4000+(2500*0.7+2500*0.3*50/70)+(IF(50<=50,3000,3000*2))+500+3000+5000+2000)*0.15))+(((IF(50<=60,13000*0.85,IF(50<=85,13000,13000*1.15)))+3500+55*50*2+30*ROUND(50*'РАСХОДЫ'!$C$3,0)+90*ROUND(50*'РАСХОДЫ'!$C$3,0)+90*ROUND(50*'РАСХОДЫ'!$C$3,0)+75*ROUND(50*'РАСХОДЫ'!$C$3,0)+60*ROUND(50*'РАСХОДЫ'!$C$3,0)+5000+5000+(IF(50<=50,8000,IF(50<=75,8000*1.2,8000*1.4)))+2500+4000+(2500*0.7+2500*0.3*50/70)+(IF(50<=50,3000,3000*2))+500+3000+5000+2000)*0.1)+0.04*((ROUND(50*'ДОХОДЫ'!$C$2*(1-'РАСХОДЫ'!$C$3),0))*('ДОХОДЫ'!$C$3*290+(1-'ДОХОДЫ'!$C$3)*377)+(ROUND(50*'ДОХОДЫ'!$C$2*'РАСХОДЫ'!$C$3,0))*('ДОХОДЫ'!$C$3*590+(1-'ДОХОДЫ'!$C$3)*767)+(MAX(ROUND(50*(1-'ДОХОДЫ'!$C$2)*(1-'РАСХОДЫ'!$C$3),0),0))*('ДОХОДЫ'!$C$3*490+(1-'ДОХОДЫ'!$C$3)*637)+(MAX(ROUND(50*(1-'ДОХОДЫ'!$C$2)*'РАСХОДЫ'!$C$3,0)-'ДОХОДЫ'!$C$10,0))*('ДОХОДЫ'!$C$3*890+(1-'ДОХОДЫ'!$C$3)*1157)+'ДОХОДЫ'!$C$5*500+'ДОХОДЫ'!$C$6*1500+'ДОХОДЫ'!$C$7*3000+'ДОХОДЫ'!$C$8*8000+'ДОХОДЫ'!$C$9*15000) | C16: =(ROUND(50*'ДОХОДЫ'!$C$2*(1-'РАСХОДЫ'!$C$3),0))*('ДОХОДЫ'!$C$3*290+(1-'ДОХОДЫ'!$C$3)*377)+(ROUND(50*'ДОХОДЫ'!$C$2*'РАСХОДЫ'!$C$3,0))*('ДОХОДЫ'!$C$3*590+(1-'ДОХОДЫ'!$C$3)*767)+(MAX(ROUND(50*(1-'ДОХОДЫ'!$C$2)*(1-'РАСХОДЫ'!$C$3),0),0))*('ДОХОДЫ'!$C$3*490+(1-'ДОХОДЫ'!$C$3)*637)+(MAX(ROUND(50*(1-'ДОХОДЫ'!$C$2)*'РАСХОДЫ'!$C$3,0)-'ДОХОДЫ'!$C$10,0))*('ДОХОДЫ'!$C$3*890+(1-'ДОХОДЫ'!$C$3)*1157)+'ДОХОДЫ'!$C$5*500+'ДОХОДЫ'!$C$6*1500+'ДОХОДЫ'!$C$7*3000+'ДОХОДЫ'!$C$8*8000+'ДОХОДЫ'!$C$9*15000 | D16: =C16-B16 | E16: =IF(C16=0,0,D16/C16)
A17: 55 | B17: =((IF(55<=60,13000*0.85,IF(55<=85,13000,13000*1.15)))+3500+55*55*2+30*ROUND(55*'РАСХОДЫ'!$C$3,0)+90*ROUND(55*'РАСХОДЫ'!$C$3,0)+90*ROUND(55*'РАСХОДЫ'!$C$3,0)+75*ROUND(55*'РАСХОДЫ'!$C$3,0)+60*ROUND(55*'РАСХОДЫ'!$C$3,0)+5000+5000+(IF(55<=50,8000,IF(55<=75,8000*1.2,8000*1.4)))+2500+4000+(2500*0.7+2500*0.3*55/70)+(IF(55<=50,3000,3000*2))+500+3000+5000+2000)+(IF('РАСХОДЫ'!$C$4="Да",0,((IF(55<=60,13000*0.85,IF(55<=85,13000,13000*1.15)))+3500+55*55*2+30*ROUND(55*'РАСХОДЫ'!$C$3,0)+90*ROUND(55*'РАСХОДЫ'!$C$3,0)+90*ROUND(55*'РАСХОДЫ'!$C$3,0)+75*ROUND(55*'РАСХОДЫ'!$C$3,0)+60*ROUND(55*'РАСХОДЫ'!$C$3,0)+5000+5000+(IF(55<=50,8000,IF(55<=75,8000*1.2,8000*1.4)))+2500+4000+(2500*0.7+2500*0.3*55/70)+(IF(55<=50,3000,3000*2))+500+3000+5000+2000)*0.15))+(((IF(55<=60,13000*0.85,IF(55<=85,13000,13000*1.15)))+3500+55*55*2+30*ROUND(55*'РАСХОДЫ'!$C$3,0)+90*ROUND(55*'РАСХОДЫ'!$C$3,0)+90*ROUND(55*'РАСХОДЫ'!$C$3,0)+75*ROUND(55*'РАСХОДЫ'!$C$3,0)+60*ROUND(55*'РАСХОДЫ'!$C$3,0)+5000+5000+(IF(55<=50,8000,IF(55<=75,8000*1.2,8000*1.4)))+2500+4000+(2500*0.7+2500*0.3*55/70)+(IF(55<=50,3000,3000*2))+500+3000+5000+2000)*0.1)+0.04*((ROUND(55*'ДОХОДЫ'!$C$2*(1-'РАСХОДЫ'!$C$3),0))*('ДОХОДЫ'!$C$3*290+(1-'ДОХОДЫ'!$C$3)*377)+(ROUND(55*'ДОХОДЫ'!$C$2*'РАСХОДЫ'!$C$3,0))*('ДОХОДЫ'!$C$3*590+(1-'ДОХОДЫ'!$C$3)*767)+(MAX(ROUND(55*(1-'ДОХОДЫ'!$C$2)*(1-'РАСХОДЫ'!$C$3),0),0))*('ДОХОДЫ'!$C$3*490+(1-'ДОХОДЫ'!$C$3)*637)+(MAX(ROUND(55*(1-'ДОХОДЫ'!$C$2)*'РАСХОДЫ'!$C$3,0)-'ДОХОДЫ'!$C$10,0))*('ДОХОДЫ'!$C$3*890+(1-'ДОХОДЫ'!$C$3)*1157)+'ДОХОДЫ'!$C$5*500+'ДОХОДЫ'!$C$6*1500+'ДОХОДЫ'!$C$7*3000+'ДОХОДЫ'!$C$8*8000+'ДОХОДЫ'!$C$9*15000) | C17: =(ROUND(55*'ДОХОДЫ'!$C$2*(1-'РАСХОДЫ'!$C$3),0))*('ДОХОДЫ'!$C$3*290+(1-'ДОХОДЫ'!$C$3)*377)+(ROUND(55*'ДОХОДЫ'!$C$2*'РАСХОДЫ'!$C$3,0))*('ДОХОДЫ'!$C$3*590+(1-'ДОХОДЫ'!$C$3)*767)+(MAX(ROUND(55*(1-'ДОХОДЫ'!$C$2)*(1-'РАСХОДЫ'!$C$3),0),0))*('ДОХОДЫ'!$C$3*490+(1-'ДОХОДЫ'!$C$3)*637)+(MAX(ROUND(55*(1-'ДОХОДЫ'!$C$2)*'РАСХОДЫ'!$C$3,0)-'ДОХОДЫ'!$C$10,0))*('ДОХОДЫ'!$C$3*890+(1-'ДОХОДЫ'!$C$3)*1157)+'ДОХОДЫ'!$C$5*500+'ДОХОДЫ'!$C$6*1500+'ДОХОДЫ'!$C$7*3000+'ДОХОДЫ'!$C$8*8000+'ДОХОДЫ'!$C$9*15000 | D17: =C17-B17 | E17: =IF(C17=0,0,D17/C17)
A18: 60 | B18: =((IF(60<=60,13000*0.85,IF(60<=85,13000,13000*1.15)))+3500+55*60*2+30*ROUND(60*'РАСХОДЫ'!$C$3,0)+90*ROUND(60*'РАСХОДЫ'!$C$3,0)+90*ROUND(60*'РАСХОДЫ'!$C$3,0)+75*ROUND(60*'РАСХОДЫ'!$C$3,0)+60*ROUND(60*'РАСХОДЫ'!$C$3,0)+5000+5000+(IF(60<=50,8000,IF(60<=75,8000*1.2,8000*1.4)))+2500+4000+(2500*0.7+2500*0.3*60/70)+(IF(60<=50,3000,3000*2))+500+3000+5000+2000)+(IF('РАСХОДЫ'!$C$4="Да",0,((IF(60<=60,13000*0.85,IF(60<=85,13000,13000*1.15)))+3500+55*60*2+30*ROUND(60*'РАСХОДЫ'!$C$3,0)+90*ROUND(60*'РАСХОДЫ'!$C$3,0)+90*ROUND(60*'РАСХОДЫ'!$C$3,0)+75*ROUND(60*'РАСХОДЫ'!$C$3,0)+60*ROUND(60*'РАСХОДЫ'!$C$3,0)+5000+5000+(IF(60<=50,8000,IF(60<=75,8000*1.2,8000*1.4)))+2500+4000+(2500*0.7+2500*0.3*60/70)+(IF(60<=50,3000,3000*2))+500+3000+5000+2000)*0.15))+(((IF(60<=60,13000*0.85,IF(60<=85,13000,13000*1.15)))+3500+55*60*2+30*ROUND(60*'РАСХОДЫ'!$C$3,0)+90*ROUND(60*'РАСХОДЫ'!$C$3,0)+90*ROUND(60*'РАСХОДЫ'!$C$3,0)+75*ROUND(60*'РАСХОДЫ'!$C$3,0)+60*ROUND(60*'РАСХОДЫ'!$C$3,0)+5000+5000+(IF(60<=50,8000,IF(60<=75,8000*1.2,8000*1.4)))+2500+4000+(2500*0.7+2500*0.3*60/70)+(IF(60<=50,3000,3000*2))+500+3000+5000+2000)*0.1)+0.04*((ROUND(60*'ДОХОДЫ'!$C$2*(1-'РАСХОДЫ'!$C$3),0))*('ДОХОДЫ'!$C$3*290+(1-'ДОХОДЫ'!$C$3)*377)+(ROUND(60*'ДОХОДЫ'!$C$2*'РАСХОДЫ'!$C$3,0))*('ДОХОДЫ'!$C$3*590+(1-'ДОХОДЫ'!$C$3)*767)+(MAX(ROUND(60*(1-'ДОХОДЫ'!$C$2)*(1-'РАСХОДЫ'!$C$3),0),0))*('ДОХОДЫ'!$C$3*490+(1-'ДОХОДЫ'!$C$3)*637)+(MAX(ROUND(60*(1-'ДОХОДЫ'!$C$2)*'РАСХОДЫ'!$C$3,0)-'ДОХОДЫ'!$C$10,0))*('ДОХОДЫ'!$C$3*890+(1-'ДОХОДЫ'!$C$3)*1157)+'ДОХОДЫ'!$C$5*500+'ДОХОДЫ'!$C$6*1500+'ДОХОДЫ'!$C$7*3000+'ДОХОДЫ'!$C$8*8000+'ДОХОДЫ'!$C$9*15000) | C18: =(ROUND(60*'ДОХОДЫ'!$C$2*(1-'РАСХОДЫ'!$C$3),0))*('ДОХОДЫ'!$C$3*290+(1-'ДОХОДЫ'!$C$3)*377)+(ROUND(60*'ДОХОДЫ'!$C$2*'РАСХОДЫ'!$C$3,0))*('ДОХОДЫ'!$C$3*590+(1-'ДОХОДЫ'!$C$3)*767)+(MAX(ROUND(60*(1-'ДОХОДЫ'!$C$2)*(1-'РАСХОДЫ'!$C$3),0),0))*('ДОХОДЫ'!$C$3*490+(1-'ДОХОДЫ'!$C$3)*637)+(MAX(ROUND(60*(1-'ДОХОДЫ'!$C$2)*'РАСХОДЫ'!$C$3,0)-'ДОХОДЫ'!$C$10,0))*('ДОХОДЫ'!$C$3*890+(1-'ДОХОДЫ'!$C$3)*1157)+'ДОХОДЫ'!$C$5*500+'ДОХОДЫ'!$C$6*1500+'ДОХОДЫ'!$C$7*3000+'ДОХОДЫ'!$C$8*8000+'ДОХОДЫ'!$C$9*15000 | D18: =C18-B18 | E18: =IF(C18=0,0,D18/C18)
A19: 65 | B19: =((IF(65<=60,13000*0.85,IF(65<=85,13000,13000*1.15)))+3500+55*65*2+30*ROUND(65*'РАСХОДЫ'!$C$3,0)+90*ROUND(65*'РАСХОДЫ'!$C$3,0)+90*ROUND(65*'РАСХОДЫ'!$C$3,0)+75*ROUND(65*'РАСХОДЫ'!$C$3,0)+60*ROUND(65*'РАСХОДЫ'!$C$3,0)+5000+5000+(IF(65<=50,8000,IF(65<=75,8000*1.2,8000*1.4)))+2500+4000+(2500*0.7+2500*0.3*65/70)+(IF(65<=50,3000,3000*2))+500+3000+5000+2000)+(IF('РАСХОДЫ'!$C$4="Да",0,((IF(65<=60,13000*0.85,IF(65<=85,13000,13000*1.15)))+3500+55*65*2+30*ROUND(65*'РАСХОДЫ'!$C$3,0)+90*ROUND(65*'РАСХОДЫ'!$C$3,0)+90*ROUND(65*'РАСХОДЫ'!$C$3,0)+75*ROUND(65*'РАСХОДЫ'!$C$3,0)+60*ROUND(65*'РАСХОДЫ'!$C$3,0)+5000+5000+(IF(65<=50,8000,IF(65<=75,8000*1.2,8000*1.4)))+2500+4000+(2500*0.7+2500*0.3*65/70)+(IF(65<=50,3000,3000*2))+500+3000+5000+2000)*0.15))+(((IF(65<=60,13000*0.85,IF(65<=85,13000,13000*1.15)))+3500+55*65*2+30*ROUND(65*'РАСХОДЫ'!$C$3,0)+90*ROUND(65*'РАСХОДЫ'!$C$3,0)+90*ROUND(65*'РАСХОДЫ'!$C$3,0)+75*ROUND(65*'РАСХОДЫ'!$C$3,0)+60*ROUND(65*'РАСХОДЫ'!$C$3,0)+5000+5000+(IF(65<=50,8000,IF(65<=75,8000*1.2,8000*1.4)))+2500+4000+(2500*0.7+2500*0.3*65/70)+(IF(65<=50,3000,3000*2))+500+3000+5000+2000)*0.1)+0.04*((ROUND(65*'ДОХОДЫ'!$C$2*(1-'РАСХОДЫ'!$C$3),0))*('ДОХОДЫ'!$C$3*290+(1-'ДОХОДЫ'!$C$3)*377)+(ROUND(65*'ДОХОДЫ'!$C$2*'РАСХОДЫ'!$C$3,0))*('ДОХОДЫ'!$C$3*590+(1-'ДОХОДЫ'!$C$3)*767)+(MAX(ROUND(65*(1-'ДОХОДЫ'!$C$2)*(1-'РАСХОДЫ'!$C$3),0),0))*('ДОХОДЫ'!$C$3*490+(1-'ДОХОДЫ'!$C$3)*637)+(MAX(ROUND(65*(1-'ДОХОДЫ'!$C$2)*'РАСХОДЫ'!$C$3,0)-'ДОХОДЫ'!$C$10,0))*('ДОХОДЫ'!$C$3*890+(1-'ДОХОДЫ'!$C$3)*1157)+'ДОХОДЫ'!$C$5*500+'ДОХОДЫ'!$C$6*1500+'ДОХОДЫ'!$C$7*3000+'ДОХОДЫ'!$C$8*8000+'ДОХОДЫ'!$C$9*15000) | C19: =(ROUND(65*'ДОХОДЫ'!$C$2*(1-'РАСХОДЫ'!$C$3),0))*('ДОХОДЫ'!$C$3*290+(1-'ДОХОДЫ'!$C$3)*377)+(ROUND(65*'ДОХОДЫ'!$C$2*'РАСХОДЫ'!$C$3,0))*('ДОХОДЫ'!$C$3*590+(1-'ДОХОДЫ'!$C$3)*767)+(MAX(ROUND(65*(1-'ДОХОДЫ'!$C$2)*(1-'РАСХОДЫ'!$C$3),0),0))*('ДОХОДЫ'!$C$3*490+(1-'ДОХОДЫ'!$C$3)*637)+(MAX(ROUND(65*(1-'ДОХОДЫ'!$C$2)*'РАСХОДЫ'!$C$3,0)-'ДОХОДЫ'!$C$10,0))*('ДОХОДЫ'!$C$3*890+(1-'ДОХОДЫ'!$C$3)*1157)+'ДОХОДЫ'!$C$5*500+'ДОХОДЫ'!$C$6*1500+'ДОХОДЫ'!$C$7*3000+'ДОХОДЫ'!$C$8*8000+'ДОХОДЫ'!$C$9*15000 | D19: =C19-B19 | E19: =IF(C19=0,0,D19/C19)
A20: 70 | B20: =((IF(70<=60,13000*0.85,IF(70<=85,13000,13000*1.15)))+3500+55*70*2+30*ROUND(70*'РАСХОДЫ'!$C$3,0)+90*ROUND(70*'РАСХОДЫ'!$C$3,0)+90*ROUND(70*'РАСХОДЫ'!$C$3,0)+75*ROUND(70*'РАСХОДЫ'!$C$3,0)+60*ROUND(70*'РАСХОДЫ'!$C$3,0)+5000+5000+(IF(70<=50,8000,IF(70<=75,8000*1.2,8000*1.4)))+2500+4000+(2500*0.7+2500*0.3*70/70)+(IF(70<=50,3000,3000*2))+500+3000+5000+2000)+(IF('РАСХОДЫ'!$C$4="Да",0,((IF(70<=60,13000*0.85,IF(70<=85,13000,13000*1.15)))+3500+55*70*2+30*ROUND(70*'РАСХОДЫ'!$C$3,0)+90*ROUND(70*'РАСХОДЫ'!$C$3,0)+90*ROUND(70*'РАСХОДЫ'!$C$3,0)+75*ROUND(70*'РАСХОДЫ'!$C$3,0)+60*ROUND(70*'РАСХОДЫ'!$C$3,0)+5000+5000+(IF(70<=50,8000,IF(70<=75,8000*1.2,8000*1.4)))+2500+4000+(2500*0.7+2500*0.3*70/70)+(IF(70<=50,3000,3000*2))+500+3000+5000+2000)*0.15))+(((IF(70<=60,13000*0.85,IF(70<=85,13000,13000*1.15)))+3500+55*70*2+30*ROUND(70*'РАСХОДЫ'!$C$3,0)+90*ROUND(70*'РАСХОДЫ'!$C$3,0)+90*ROUND(70*'РАСХОДЫ'!$C$3,0)+75*ROUND(70*'РАСХОДЫ'!$C$3,0)+60*ROUND(70*'РАСХОДЫ'!$C$3,0)+5000+5000+(IF(70<=50,8000,IF(70<=75,8000*1.2,8000*1.4)))+2500+4000+(2500*0.7+2500*0.3*70/70)+(IF(70<=50,3000,3000*2))+500+3000+5000+2000)*0.1)+0.04*((ROUND(70*'ДОХОДЫ'!$C$2*(1-'РАСХОДЫ'!$C$3),0))*('ДОХОДЫ'!$C$3*290+(1-'ДОХОДЫ'!$C$3)*377)+(ROUND(70*'ДОХОДЫ'!$C$2*'РАСХОДЫ'!$C$3,0))*('ДОХОДЫ'!$C$3*590+(1-'ДОХОДЫ'!$C$3)*767)+(MAX(ROUND(70*(1-'ДОХОДЫ'!$C$2)*(1-'РАСХОДЫ'!$C$3),0),0))*('ДОХОДЫ'!$C$3*490+(1-'ДОХОДЫ'!$C$3)*637)+(MAX(ROUND(70*(1-'ДОХОДЫ'!$C$2)*'РАСХОДЫ'!$C$3,0)-'ДОХОДЫ'!$C$10,0))*('ДОХОДЫ'!$C$3*890+(1-'ДОХОДЫ'!$C$3)*1157)+'ДОХОДЫ'!$C$5*500+'ДОХОДЫ'!$C$6*1500+'ДОХОДЫ'!$C$7*3000+'ДОХОДЫ'!$C$8*8000+'ДОХОДЫ'!$C$9*15000) | C20: =(ROUND(70*'ДОХОДЫ'!$C$2*(1-'РАСХОДЫ'!$C$3),0))*('ДОХОДЫ'!$C$3*290+(1-'ДОХОДЫ'!$C$3)*377)+(ROUND(70*'ДОХОДЫ'!$C$2*'РАСХОДЫ'!$C$3,0))*('ДОХОДЫ'!$C$3*590+(1-'ДОХОДЫ'!$C$3)*767)+(MAX(ROUND(70*(1-'ДОХОДЫ'!$C$2)*(1-'РАСХОДЫ'!$C$3),0),0))*('ДОХОДЫ'!$C$3*490+(1-'ДОХОДЫ'!$C$3)*637)+(MAX(ROUND(70*(1-'ДОХОДЫ'!$C$2)*'РАСХОДЫ'!$C$3,0)-'ДОХОДЫ'!$C$10,0))*('ДОХОДЫ'!$C$3*890+(1-'ДОХОДЫ'!$C$3)*1157)+'ДОХОДЫ'!$C$5*500+'ДОХОДЫ'!$C$6*1500+'ДОХОДЫ'!$C$7*3000+'ДОХОДЫ'!$C$8*8000+'ДОХОДЫ'!$C$9*15000 | D20: =C20-B20 | E20: =IF(C20=0,0,D20/C20)
A21: 75 | B21: =((IF(75<=60,13000*0.85,IF(75<=85,13000,13000*1.15)))+3500+55*75*2+30*ROUND(75*'РАСХОДЫ'!$C$3,0)+90*ROUND(75*'РАСХОДЫ'!$C$3,0)+90*ROUND(75*'РАСХОДЫ'!$C$3,0)+75*ROUND(75*'РАСХОДЫ'!$C$3,0)+60*ROUND(75*'РАСХОДЫ'!$C$3,0)+5000+5000+(IF(75<=50,8000,IF(75<=75,8000*1.2,8000*1.4)))+2500+4000+(2500*0.7+2500*0.3*75/70)+(IF(75<=50,3000,3000*2))+500+3000+5000+2000)+(IF('РАСХОДЫ'!$C$4="Да",0,((IF(75<=60,13000*0.85,IF(75<=85,13000,13000*1.15)))+3500+55*75*2+30*ROUND(75*'РАСХОДЫ'!$C$3,0)+90*ROUND(75*'РАСХОДЫ'!$C$3,0)+90*ROUND(75*'РАСХОДЫ'!$C$3,0)+75*ROUND(75*'РАСХОДЫ'!$C$3,0)+60*ROUND(75*'РАСХОДЫ'!$C$3,0)+5000+5000+(IF(75<=50,8000,IF(75<=75,8000*1.2,8000*1.4)))+2500+4000+(2500*0.7+2500*0.3*75/70)+(IF(75<=50,3000,3000*2))+500+3000+5000+2000)*0.15))+(((IF(75<=60,13000*0.85,IF(75<=85,13000,13000*1.15)))+3500+55*75*2+30*ROUND(75*'РАСХОДЫ'!$C$3,0)+90*ROUND(75*'РАСХОДЫ'!$C$3,0)+90*ROUND(75*'РАСХОДЫ'!$C$3,0)+75*ROUND(75*'РАСХОДЫ'!$C$3,0)+60*ROUND(75*'РАСХОДЫ'!$C$3,0)+5000+5000+(IF(75<=50,8000,IF(75<=75,8000*1.2,8000*1.4)))+2500+4000+(2500*0.7+2500*0.3*75/70)+(IF(75<=50,3000,3000*2))+500+3000+5000+2000)*0.1)+0.04*((ROUND(75*'ДОХОДЫ'!$C$2*(1-'РАСХОДЫ'!$C$3),0))*('ДОХОДЫ'!$C$3*290+(1-'ДОХОДЫ'!$C$3)*377)+(ROUND(75*'ДОХОДЫ'!$C$2*'РАСХОДЫ'!$C$3,0))*('ДОХОДЫ'!$C$3*590+(1-'ДОХОДЫ'!$C$3)*767)+(MAX(ROUND(75*(1-'ДОХОДЫ'!$C$2)*(1-'РАСХОДЫ'!$C$3),0),0))*('ДОХОДЫ'!$C$3*490+(1-'ДОХОДЫ'!$C$3)*637)+(MAX(ROUND(75*(1-'ДОХОДЫ'!$C$2)*'РАСХОДЫ'!$C$3,0)-'ДОХОДЫ'!$C$10,0))*('ДОХОДЫ'!$C$3*890+(1-'ДОХОДЫ'!$C$3)*1157)+'ДОХОДЫ'!$C$5*500+'ДОХОДЫ'!$C$6*1500+'ДОХОДЫ'!$C$7*3000+'ДОХОДЫ'!$C$8*8000+'ДОХОДЫ'!$C$9*15000) | C21: =(ROUND(75*'ДОХОДЫ'!$C$2*(1-'РАСХОДЫ'!$C$3),0))*('ДОХОДЫ'!$C$3*290+(1-'ДОХОДЫ'!$C$3)*377)+(ROUND(75*'ДОХОДЫ'!$C$2*'РАСХОДЫ'!$C$3,0))*('ДОХОДЫ'!$C$3*590+(1-'ДОХОДЫ'!$C$3)*767)+(MAX(ROUND(75*(1-'ДОХОДЫ'!$C$2)*(1-'РАСХОДЫ'!$C$3),0),0))*('ДОХОДЫ'!$C$3*490+(1-'ДОХОДЫ'!$C$3)*637)+(MAX(ROUND(75*(1-'ДОХОДЫ'!$C$2)*'РАСХОДЫ'!$C$3,0)-'ДОХОДЫ'!$C$10,0))*('ДОХОДЫ'!$C$3*890+(1-'ДОХОДЫ'!$C$3)*1157)+'ДОХОДЫ'!$C$5*500+'ДОХОДЫ'!$C$6*1500+'ДОХОДЫ'!$C$7*3000+'ДОХОДЫ'!$C$8*8000+'ДОХОДЫ'!$C$9*15000 | D21: =C21-B21 | E21: =IF(C21=0,0,D21/C21)
A22: 80 | B22: =((IF(80<=60,13000*0.85,IF(80<=85,13000,13000*1.15)))+3500+55*80*2+30*ROUND(80*'РАСХОДЫ'!$C$3,0)+90*ROUND(80*'РАСХОДЫ'!$C$3,0)+90*ROUND(80*'РАСХОДЫ'!$C$3,0)+75*ROUND(80*'РАСХОДЫ'!$C$3,0)+60*ROUND(80*'РАСХОДЫ'!$C$3,0)+5000+5000+(IF(80<=50,8000,IF(80<=75,8000*1.2,8000*1.4)))+2500+4000+(2500*0.7+2500*0.3*80/70)+(IF(80<=50,3000,3000*2))+500+3000+5000+2000)+(IF('РАСХОДЫ'!$C$4="Да",0,((IF(80<=60,13000*0.85,IF(80<=85,13000,13000*1.15)))+3500+55*80*2+30*ROUND(80*'РАСХОДЫ'!$C$3,0)+90*ROUND(80*'РАСХОДЫ'!$C$3,0)+90*ROUND(80*'РАСХОДЫ'!$C$3,0)+75*ROUND(80*'РАСХОДЫ'!$C$3,0)+60*ROUND(80*'РАСХОДЫ'!$C$3,0)+5000+5000+(IF(80<=50,8000,IF(80<=75,8000*1.2,8000*1.4)))+2500+4000+(2500*0.7+2500*0.3*80/70)+(IF(80<=50,3000,3000*2))+500+3000+5000+2000)*0.15))+(((IF(80<=60,13000*0.85,IF(80<=85,13000,13000*1.15)))+3500+55*80*2+30*ROUND(80*'РАСХОДЫ'!$C$3,0)+90*ROUND(80*'РАСХОДЫ'!$C$3,0)+90*ROUND(80*'РАСХОДЫ'!$C$3,0)+75*ROUND(80*'РАСХОДЫ'!$C$3,0)+60*ROUND(80*'РАСХОДЫ'!$C$3,0)+5000+5000+(IF(80<=50,8000,IF(80<=75,8000*1.2,8000*1.4)))+2500+4000+(2500*0.7+2500*0.3*80/70)+(IF(80<=50,3000,3000*2))+500+3000+5000+2000)*0.1)+0.04*((ROUND(80*'ДОХОДЫ'!$C$2*(1-'РАСХОДЫ'!$C$3),0))*('ДОХОДЫ'!$C$3*290+(1-'ДОХОДЫ'!$C$3)*377)+(ROUND(80*'ДОХОДЫ'!$C$2*'РАСХОДЫ'!$C$3,0))*('ДОХОДЫ'!$C$3*590+(1-'ДОХОДЫ'!$C$3)*767)+(MAX(ROUND(80*(1-'ДОХОДЫ'!$C$2)*(1-'РАСХОДЫ'!$C$3),0),0))*('ДОХОДЫ'!$C$3*490+(1-'ДОХОДЫ'!$C$3)*637)+(MAX(ROUND(80*(1-'ДОХОДЫ'!$C$2)*'РАСХОДЫ'!$C$3,0)-'ДОХОДЫ'!$C$10,0))*('ДОХОДЫ'!$C$3*890+(1-'ДОХОДЫ'!$C$3)*1157)+'ДОХОДЫ'!$C$5*500+'ДОХОДЫ'!$C$6*1500+'ДОХОДЫ'!$C$7*3000+'ДОХОДЫ'!$C$8*8000+'ДОХОДЫ'!$C$9*15000) | C22: =(ROUND(80*'ДОХОДЫ'!$C$2*(1-'РАСХОДЫ'!$C$3),0))*('ДОХОДЫ'!$C$3*290+(1-'ДОХОДЫ'!$C$3)*377)+(ROUND(80*'ДОХОДЫ'!$C$2*'РАСХОДЫ'!$C$3,0))*('ДОХОДЫ'!$C$3*590+(1-'ДОХОДЫ'!$C$3)*767)+(MAX(ROUND(80*(1-'ДОХОДЫ'!$C$2)*(1-'РАСХОДЫ'!$C$3),0),0))*('ДОХОДЫ'!$C$3*490+(1-'ДОХОДЫ'!$C$3)*637)+(MAX(ROUND(80*(1-'ДОХОДЫ'!$C$2)*'РАСХОДЫ'!$C$3,0)-'ДОХОДЫ'!$C$10,0))*('ДОХОДЫ'!$C$3*890+(1-'ДОХОДЫ'!$C$3)*1157)+'ДОХОДЫ'!$C$5*500+'ДОХОДЫ'!$C$6*1500+'ДОХОДЫ'!$C$7*3000+'ДОХОДЫ'!$C$8*8000+'ДОХОДЫ'!$C$9*15000 | D22: =C22-B22 | E22: =IF(C22=0,0,D22/C22)
A23: 85 | B23: =((IF(85<=60,13000*0.85,IF(85<=85,13000,13000*1.15)))+3500+55*85*2+30*ROUND(85*'РАСХОДЫ'!$C$3,0)+90*ROUND(85*'РАСХОДЫ'!$C$3,0)+90*ROUND(85*'РАСХОДЫ'!$C$3,0)+75*ROUND(85*'РАСХОДЫ'!$C$3,0)+60*ROUND(85*'РАСХОДЫ'!$C$3,0)+5000+5000+(IF(85<=50,8000,IF(85<=75,8000*1.2,8000*1.4)))+2500+4000+(2500*0.7+2500*0.3*85/70)+(IF(85<=50,3000,3000*2))+500+3000+5000+2000)+(IF('РАСХОДЫ'!$C$4="Да",0,((IF(85<=60,13000*0.85,IF(85<=85,13000,13000*1.15)))+3500+55*85*2+30*ROUND(85*'РАСХОДЫ'!$C$3,0)+90*ROUND(85*'РАСХОДЫ'!$C$3,0)+90*ROUND(85*'РАСХОДЫ'!$C$3,0)+75*ROUND(85*'РАСХОДЫ'!$C$3,0)+60*ROUND(85*'РАСХОДЫ'!$C$3,0)+5000+5000+(IF(85<=50,8000,IF(85<=75,8000*1.2,8000*1.4)))+2500+4000+(2500*0.7+2500*0.3*85/70)+(IF(85<=50,3000,3000*2))+500+3000+5000+2000)*0.15))+(((IF(85<=60,13000*0.85,IF(85<=85,13000,13000*1.15)))+3500+55*85*2+30*ROUND(85*'РАСХОДЫ'!$C$3,0)+90*ROUND(85*'РАСХОДЫ'!$C$3,0)+90*ROUND(85*'РАСХОДЫ'!$C$3,0)+75*ROUND(85*'РАСХОДЫ'!$C$3,0)+60*ROUND(85*'РАСХОДЫ'!$C$3,0)+5000+5000+(IF(85<=50,8000,IF(85<=75,8000*1.2,8000*1.4)))+2500+4000+(2500*0.7+2500*0.3*85/70)+(IF(85<=50,3000,3000*2))+500+3000+5000+2000)*0.1)+0.04*((ROUND(85*'ДОХОДЫ'!$C$2*(1-'РАСХОДЫ'!$C$3),0))*('ДОХОДЫ'!$C$3*290+(1-'ДОХОДЫ'!$C$3)*377)+(ROUND(85*'ДОХОДЫ'!$C$2*'РАСХОДЫ'!$C$3,0))*('ДОХОДЫ'!$C$3*590+(1-'ДОХОДЫ'!$C$3)*767)+(MAX(ROUND(85*(1-'ДОХОДЫ'!$C$2)*(1-'РАСХОДЫ'!$C$3),0),0))*('ДОХОДЫ'!$C$3*490+(1-'ДОХОДЫ'!$C$3)*637)+(MAX(ROUND(85*(1-'ДОХОДЫ'!$C$2)*'РАСХОДЫ'!$C$3,0)-'ДОХОДЫ'!$C$10,0))*('ДОХОДЫ'!$C$3*890+(1-'ДОХОДЫ'!$C$3)*1157)+'ДОХОДЫ'!$C$5*500+'ДОХОДЫ'!$C$6*1500+'ДОХОДЫ'!$C$7*3000+'ДОХОДЫ'!$C$8*8000+'ДОХОДЫ'!$C$9*15000) | C23: =(ROUND(85*'ДОХОДЫ'!$C$2*(1-'РАСХОДЫ'!$C$3),0))*('ДОХОДЫ'!$C$3*290+(1-'ДОХОДЫ'!$C$3)*377)+(ROUND(85*'ДОХОДЫ'!$C$2*'РАСХОДЫ'!$C$3,0))*('ДОХОДЫ'!$C$3*590+(1-'ДОХОДЫ'!$C$3)*767)+(MAX(ROUND(85*(1-'ДОХОДЫ'!$C$2)*(1-'РАСХОДЫ'!$C$3),0),0))*('ДОХОДЫ'!$C$3*490+(1-'ДОХОДЫ'!$C$3)*637)+(MAX(ROUND(85*(1-'ДОХОДЫ'!$C$2)*'РАСХОДЫ'!$C$3,0)-'ДОХОДЫ'!$C$10,0))*('ДОХОДЫ'!$C$3*890+(1-'ДОХОДЫ'!$C$3)*1157)+'ДОХОДЫ'!$C$5*500+'ДОХОДЫ'!$C$6*1500+'ДОХОДЫ'!$C$7*3000+'ДОХОДЫ'!$C$8*8000+'ДОХОДЫ'!$C$9*15000 | D23: =C23-B23 | E23: =IF(C23=0,0,D23/C23)
A24: 90 | B24: =((IF(90<=60,13000*0.85,IF(90<=85,13000,13000*1.15)))+3500+55*90*2+30*ROUND(90*'РАСХОДЫ'!$C$3,0)+90*ROUND(90*'РАСХОДЫ'!$C$3,0)+90*ROUND(90*'РАСХОДЫ'!$C$3,0)+75*ROUND(90*'РАСХОДЫ'!$C$3,0)+60*ROUND(90*'РАСХОДЫ'!$C$3,0)+5000+5000+(IF(90<=50,8000,IF(90<=75,8000*1.2,8000*1.4)))+2500+4000+(2500*0.7+2500*0.3*90/70)+(IF(90<=50,3000,3000*2))+500+3000+5000+2000)+(IF('РАСХОДЫ'!$C$4="Да",0,((IF(90<=60,13000*0.85,IF(90<=85,13000,13000*1.15)))+3500+55*90*2+30*ROUND(90*'РАСХОДЫ'!$C$3,0)+90*ROUND(90*'РАСХОДЫ'!$C$3,0)+90*ROUND(90*'РАСХОДЫ'!$C$3,0)+75*ROUND(90*'РАСХОДЫ'!$C$3,0)+60*ROUND(90*'РАСХОДЫ'!$C$3,0)+5000+5000+(IF(90<=50,8000,IF(90<=75,8000*1.2,8000*1.4)))+2500+4000+(2500*0.7+2500*0.3*90/70)+(IF(90<=50,3000,3000*2))+500+3000+5000+2000)*0.15))+(((IF(90<=60,13000*0.85,IF(90<=85,13000,13000*1.15)))+3500+55*90*2+30*ROUND(90*'РАСХОДЫ'!$C$3,0)+90*ROUND(90*'РАСХОДЫ'!$C$3,0)+90*ROUND(90*'РАСХОДЫ'!$C$3,0)+75*ROUND(90*'РАСХОДЫ'!$C$3,0)+60*ROUND(90*'РАСХОДЫ'!$C$3,0)+5000+5000+(IF(90<=50,8000,IF(90<=75,8000*1.2,8000*1.4)))+2500+4000+(2500*0.7+2500*0.3*90/70)+(IF(90<=50,3000,3000*2))+500+3000+5000+2000)*0.1)+0.04*((ROUND(90*'ДОХОДЫ'!$C$2*(1-'РАСХОДЫ'!$C$3),0))*('ДОХОДЫ'!$C$3*290+(1-'ДОХОДЫ'!$C$3)*377)+(ROUND(90*'ДОХОДЫ'!$C$2*'РАСХОДЫ'!$C$3,0))*('ДОХОДЫ'!$C$3*590+(1-'ДОХОДЫ'!$C$3)*767)+(MAX(ROUND(90*(1-'ДОХОДЫ'!$C$2)*(1-'РАСХОДЫ'!$C$3),0),0))*('ДОХОДЫ'!$C$3*490+(1-'ДОХОДЫ'!$C$3)*637)+(MAX(ROUND(90*(1-'ДОХОДЫ'!$C$2)*'РАСХОДЫ'!$C$3,0)-'ДОХОДЫ'!$C$10,0))*('ДОХОДЫ'!$C$3*890+(1-'ДОХОДЫ'!$C$3)*1157)+'ДОХОДЫ'!$C$5*500+'ДОХОДЫ'!$C$6*1500+'ДОХОДЫ'!$C$7*3000+'ДОХОДЫ'!$C$8*8000+'ДОХОДЫ'!$C$9*15000) | C24: =(ROUND(90*'ДОХОДЫ'!$C$2*(1-'РАСХОДЫ'!$C$3),0))*('ДОХОДЫ'!$C$3*290+(1-'ДОХОДЫ'!$C$3)*377)+(ROUND(90*'ДОХОДЫ'!$C$2*'РАСХОДЫ'!$C$3,0))*('ДОХОДЫ'!$C$3*590+(1-'ДОХОДЫ'!$C$3)*767)+(MAX(ROUND(90*(1-'ДОХОДЫ'!$C$2)*(1-'РАСХОДЫ'!$C$3),0),0))*('ДОХОДЫ'!$C$3*490+(1-'ДОХОДЫ'!$C$3)*637)+(MAX(ROUND(90*(1-'ДОХОДЫ'!$C$2)*'РАСХОДЫ'!$C$3,0)-'ДОХОДЫ'!$C$10,0))*('ДОХОДЫ'!$C$3*890+(1-'ДОХОДЫ'!$C$3)*1157)+'ДОХОДЫ'!$C$5*500+'ДОХОДЫ'!$C$6*1500+'ДОХОДЫ'!$C$7*3000+'ДОХОДЫ'!$C$8*8000+'ДОХОДЫ'!$C$9*15000 | D24: =C24-B24 | E24: =IF(C24=0,0,D24/C24)
A25: 95 | B25: =((IF(95<=60,13000*0.85,IF(95<=85,13000,13000*1.15)))+3500+55*95*2+30*ROUND(95*'РАСХОДЫ'!$C$3,0)+90*ROUND(95*'РАСХОДЫ'!$C$3,0)+90*ROUND(95*'РАСХОДЫ'!$C$3,0)+75*ROUND(95*'РАСХОДЫ'!$C$3,0)+60*ROUND(95*'РАСХОДЫ'!$C$3,0)+5000+5000+(IF(95<=50,8000,IF(95<=75,8000*1.2,8000*1.4)))+2500+4000+(2500*0.7+2500*0.3*95/70)+(IF(95<=50,3000,3000*2))+500+3000+5000+2000)+(IF('РАСХОДЫ'!$C$4="Да",0,((IF(95<=60,13000*0.85,IF(95<=85,13000,13000*1.15)))+3500+55*95*2+30*ROUND(95*'РАСХОДЫ'!$C$3,0)+90*ROUND(95*'РАСХОДЫ'!$C$3,0)+90*ROUND(95*'РАСХОДЫ'!$C$3,0)+75*ROUND(95*'РАСХОДЫ'!$C$3,0)+60*ROUND(95*'РАСХОДЫ'!$C$3,0)+5000+5000+(IF(95<=50,8000,IF(95<=75,8000*1.2,8000*1.4)))+2500+4000+(2500*0.7+2500*0.3*95/70)+(IF(95<=50,3000,3000*2))+500+3000+5000+2000)*0.15))+(((IF(95<=60,13000*0.85,IF(95<=85,13000,13000*1.15)))+3500+55*95*2+30*ROUND(95*'РАСХОДЫ'!$C$3,0)+90*ROUND(95*'РАСХОДЫ'!$C$3,0)+90*ROUND(95*'РАСХОДЫ'!$C$3,0)+75*ROUND(95*'РАСХОДЫ'!$C$3,0)+60*ROUND(95*'РАСХОДЫ'!$C$3,0)+5000+5000+(IF(95<=50,8000,IF(95<=75,8000*1.2,8000*1.4)))+2500+4000+(2500*0.7+2500*0.3*95/70)+(IF(95<=50,3000,3000*2))+500+3000+5000+2000)*0.1)+0.04*((ROUND(95*'ДОХОДЫ'!$C$2*(1-'РАСХОДЫ'!$C$3),0))*('ДОХОДЫ'!$C$3*290+(1-'ДОХОДЫ'!$C$3)*377)+(ROUND(95*'ДОХОДЫ'!$C$2*'РАСХОДЫ'!$C$3,0))*('ДОХОДЫ'!$C$3*590+(1-'ДОХОДЫ'!$C$3)*767)+(MAX(ROUND(95*(1-'ДОХОДЫ'!$C$2)*(1-'РАСХОДЫ'!$C$3),0),0))*('ДОХОДЫ'!$C$3*490+(1-'ДОХОДЫ'!$C$3)*637)+(MAX(ROUND(95*(1-'ДОХОДЫ'!$C$2)*'РАСХОДЫ'!$C$3,0)-'ДОХОДЫ'!$C$10,0))*('ДОХОДЫ'!$C$3*890+(1-'ДОХОДЫ'!$C$3)*1157)+'ДОХОДЫ'!$C$5*500+'ДОХОДЫ'!$C$6*1500+'ДОХОДЫ'!$C$7*3000+'ДОХОДЫ'!$C$8*8000+'ДОХОДЫ'!$C$9*15000) | C25: =(ROUND(95*'ДОХОДЫ'!$C$2*(1-'РАСХОДЫ'!$C$3),0))*('ДОХОДЫ'!$C$3*290+(1-'ДОХОДЫ'!$C$3)*377)+(ROUND(95*'ДОХОДЫ'!$C$2*'РАСХОДЫ'!$C$3,0))*('ДОХОДЫ'!$C$3*590+(1-'ДОХОДЫ'!$C$3)*767)+(MAX(ROUND(95*(1-'ДОХОДЫ'!$C$2)*(1-'РАСХОДЫ'!$C$3),0),0))*('ДОХОДЫ'!$C$3*490+(1-'ДОХОДЫ'!$C$3)*637)+(MAX(ROUND(95*(1-'ДОХОДЫ'!$C$2)*'РАСХОДЫ'!$C$3,0)-'ДОХОДЫ'!$C$10,0))*('ДОХОДЫ'!$C$3*890+(1-'ДОХОДЫ'!$C$3)*1157)+'ДОХОДЫ'!$C$5*500+'ДОХОДЫ'!$C$6*1500+'ДОХОДЫ'!$C$7*3000+'ДОХОДЫ'!$C$8*8000+'ДОХОДЫ'!$C$9*15000 | D25: =C25-B25 | E25: =IF(C25=0,0,D25/C25)
A26: 100 | B26: =((IF(100<=60,13000*0.85,IF(100<=85,13000,13000*1.15)))+3500+55*100*2+30*ROUND(100*'РАСХОДЫ'!$C$3,0)+90*ROUND(100*'РАСХОДЫ'!$C$3,0)+90*ROUND(100*'РАСХОДЫ'!$C$3,0)+75*ROUND(100*'РАСХОДЫ'!$C$3,0)+60*ROUND(100*'РАСХОДЫ'!$C$3,0)+5000+5000+(IF(100<=50,8000,IF(100<=75,8000*1.2,8000*1.4)))+2500+4000+(2500*0.7+2500*0.3*100/70)+(IF(100<=50,3000,3000*2))+500+3000+5000+2000)+(IF('РАСХОДЫ'!$C$4="Да",0,((IF(100<=60,13000*0.85,IF(100<=85,13000,13000*1.15)))+3500+55*100*2+30*ROUND(100*'РАСХОДЫ'!$C$3,0)+90*ROUND(100*'РАСХОДЫ'!$C$3,0)+90*ROUND(100*'РАСХОДЫ'!$C$3,0)+75*ROUND(100*'РАСХОДЫ'!$C$3,0)+60*ROUND(100*'РАСХОДЫ'!$C$3,0)+5000+5000+(IF(100<=50,8000,IF(100<=75,8000*1.2,8000*1.4)))+2500+4000+(2500*0.7+2500*0.3*100/70)+(IF(100<=50,3000,3000*2))+500+3000+5000+2000)*0.15))+(((IF(100<=60,13000*0.85,IF(100<=85,13000,13000*1.15)))+3500+55*100*2+30*ROUND(100*'РАСХОДЫ'!$C$3,0)+90*ROUND(100*'РАСХОДЫ'!$C$3,0)+90*ROUND(100*'РАСХОДЫ'!$C$3,0)+75*ROUND(100*'РАСХОДЫ'!$C$3,0)+60*ROUND(100*'РАСХОДЫ'!$C$3,0)+5000+5000+(IF(100<=50,8000,IF(100<=75,8000*1.2,8000*1.4)))+2500+4000+(2500*0.7+2500*0.3*100/70)+(IF(100<=50,3000,3000*2))+500+3000+5000+2000)*0.1)+0.04*((ROUND(100*'ДОХОДЫ'!$C$2*(1-'РАСХОДЫ'!$C$3),0))*('ДОХОДЫ'!$C$3*290+(1-'ДОХОДЫ'!$C$3)*377)+(ROUND(100*'ДОХОДЫ'!$C$2*'РАСХОДЫ'!$C$3,0))*('ДОХОДЫ'!$C$3*590+(1-'ДОХОДЫ'!$C$3)*767)+(MAX(ROUND(100*(1-'ДОХОДЫ'!$C$2)*(1-'РАСХОДЫ'!$C$3),0),0))*('ДОХОДЫ'!$C$3*490+(1-'ДОХОДЫ'!$C$3)*637)+(MAX(ROUND(100*(1-'ДОХОДЫ'!$C$2)*'РАСХОДЫ'!$C$3,0)-'ДОХОДЫ'!$C$10,0))*('ДОХОДЫ'!$C$3*890+(1-'ДОХОДЫ'!$C$3)*1157)+'ДОХОДЫ'!$C$5*500+'ДОХОДЫ'!$C$6*1500+'ДОХОДЫ'!$C$7*3000+'ДОХОДЫ'!$C$8*8000+'ДОХОДЫ'!$C$9*15000) | C26: =(ROUND(100*'ДОХОДЫ'!$C$2*(1-'РАСХОДЫ'!$C$3),0))*('ДОХОДЫ'!$C$3*290+(1-'ДОХОДЫ'!$C$3)*377)+(ROUND(100*'ДОХОДЫ'!$C$2*'РАСХОДЫ'!$C$3,0))*('ДОХОДЫ'!$C$3*590+(1-'ДОХОДЫ'!$C$3)*767)+(MAX(ROUND(100*(1-'ДОХОДЫ'!$C$2)*(1-'РАСХОДЫ'!$C$3),0),0))*('ДОХОДЫ'!$C$3*490+(1-'ДОХОДЫ'!$C$3)*637)+(MAX(ROUND(100*(1-'ДОХОДЫ'!$C$2)*'РАСХОДЫ'!$C$3,0)-'ДОХОДЫ'!$C$10,0))*('ДОХОДЫ'!$C$3*890+(1-'ДОХОДЫ'!$C$3)*1157)+'ДОХОДЫ'!$C$5*500+'ДОХОДЫ'!$C$6*1500+'ДОХОДЫ'!$C$7*3000+'ДОХОДЫ'!$C$8*8000+'ДОХОДЫ'!$C$9*15000 | D26: =C26-B26 | E26: =IF(C26=0,0,D26/C26)
A29: МАТРИЦА: Участники × Партнёры
A30: Участников | B30: 0 партн. | C30: 1 Partner | D30: 1P + 1S | E30: 1S + 1T | F30: 1P+1S+1T
A31: 30 | B31: =((ROUND(30*'ДОХОДЫ'!$C$2*(1-'РАСХОДЫ'!$C$3),0))*('ДОХОДЫ'!$C$3*290+(1-'ДОХОДЫ'!$C$3)*377)+(ROUND(30*'ДОХОДЫ'!$C$2*'РАСХОДЫ'!$C$3,0))*('ДОХОДЫ'!$C$3*590+(1-'ДОХОДЫ'!$C$3)*767)+(MAX(ROUND(30*(1-'ДОХОДЫ'!$C$2)*(1-'РАСХОДЫ'!$C$3),0),0))*('ДОХОДЫ'!$C$3*490+(1-'ДОХОДЫ'!$C$3)*637)+(MAX(ROUND(30*(1-'ДОХОДЫ'!$C$2)*'РАСХОДЫ'!$C$3,0)-(0*2+0*4+0*6),0))*('ДОХОДЫ'!$C$3*890+(1-'ДОХОДЫ'!$C$3)*1157)+'ДОХОДЫ'!$C$5*500+'ДОХОДЫ'!$C$6*1500+0*3000+0*8000+0*15000)-(((IF(30<=60,13000*0.85,IF(30<=85,13000,13000*1.15)))+3500+55*30*2+30*ROUND(30*'РАСХОДЫ'!$C$3,0)+90*ROUND(30*'РАСХОДЫ'!$C$3,0)+90*ROUND(30*'РАСХОДЫ'!$C$3,0)+75*ROUND(30*'РАСХОДЫ'!$C$3,0)+60*ROUND(30*'РАСХОДЫ'!$C$3,0)+5000+5000+(IF(30<=50,8000,IF(30<=75,8000*1.2,8000*1.4)))+2500+4000+(2500*0.7+2500*0.3*30/70)+(IF(30<=50,3000,3000*2))+500+3000+5000+2000)+(IF('РАСХОДЫ'!$C$4="Да",0,((IF(30<=60,13000*0.85,IF(30<=85,13000,13000*1.15)))+3500+55*30*2+30*ROUND(30*'РАСХОДЫ'!$C$3,0)+90*ROUND(30*'РАСХОДЫ'!$C$3,0)+90*ROUND(30*'РАСХОДЫ'!$C$3,0)+75*ROUND(30*'РАСХОДЫ'!$C$3,0)+60*ROUND(30*'РАСХОДЫ'!$C$3,0)+5000+5000+(IF(30<=50,8000,IF(30<=75,8000*1.2,8000*1.4)))+2500+4000+(2500*0.7+2500*0.3*30/70)+(IF(30<=50,3000,3000*2))+500+3000+5000+2000)*0.15))+(((IF(30<=60,13000*0.85,IF(30<=85,13000,13000*1.15)))+3500+55*30*2+30*ROUND(30*'РАСХОДЫ'!$C$3,0)+90*ROUND(30*'РАСХОДЫ'!$C$3,0)+90*ROUND(30*'РАСХОДЫ'!$C$3,0)+75*ROUND(30*'РАСХОДЫ'!$C$3,0)+60*ROUND(30*'РАСХОДЫ'!$C$3,0)+5000+5000+(IF(30<=50,8000,IF(30<=75,8000*1.2,8000*1.4)))+2500+4000+(2500*0.7+2500*0.3*30/70)+(IF(30<=50,3000,3000*2))+500+3000+5000+2000)*0.1))-0.04*((ROUND(30*'ДОХОДЫ'!$C$2*(1-'РАСХОДЫ'!$C$3),0))*('ДОХОДЫ'!$C$3*290+(1-'ДОХОДЫ'!$C$3)*377)+(ROUND(30*'ДОХОДЫ'!$C$2*'РАСХОДЫ'!$C$3,0))*('ДОХОДЫ'!$C$3*590+(1-'ДОХОДЫ'!$C$3)*767)+(MAX(ROUND(30*(1-'ДОХОДЫ'!$C$2)*(1-'РАСХОДЫ'!$C$3),0),0))*('ДОХОДЫ'!$C$3*490+(1-'ДОХОДЫ'!$C$3)*637)+(MAX(ROUND(30*(1-'ДОХОДЫ'!$C$2)*'РАСХОДЫ'!$C$3,0)-(0*2+0*4+0*6),0))*('ДОХОДЫ'!$C$3*890+(1-'ДОХОДЫ'!$C$3)*1157)+'ДОХОДЫ'!$C$5*500+'ДОХОДЫ'!$C$6*1500+0*3000+0*8000+0*15000) | C31: =((ROUND(30*'ДОХОДЫ'!$C$2*(1-'РАСХОДЫ'!$C$3),0))*('ДОХОДЫ'!$C$3*290+(1-'ДОХОДЫ'!$C$3)*377)+(ROUND(30*'ДОХОДЫ'!$C$2*'РАСХОДЫ'!$C$3,0))*('ДОХОДЫ'!$C$3*590+(1-'ДОХОДЫ'!$C$3)*767)+(MAX(ROUND(30*(1-'ДОХОДЫ'!$C$2)*(1-'РАСХОДЫ'!$C$3),0),0))*('ДОХОДЫ'!$C$3*490+(1-'ДОХОДЫ'!$C$3)*637)+(MAX(ROUND(30*(1-'ДОХОДЫ'!$C$2)*'РАСХОДЫ'!$C$3,0)-(1*2+0*4+0*6),0))*('ДОХОДЫ'!$C$3*890+(1-'ДОХОДЫ'!$C$3)*1157)+'ДОХОДЫ'!$C$5*500+'ДОХОДЫ'!$C$6*1500+1*3000+0*8000+0*15000)-(((IF(30<=60,13000*0.85,IF(30<=85,13000,13000*1.15)))+3500+55*30*2+30*ROUND(30*'РАСХОДЫ'!$C$3,0)+90*ROUND(30*'РАСХОДЫ'!$C$3,0)+90*ROUND(30*'РАСХОДЫ'!$C$3,0)+75*ROUND(30*'РАСХОДЫ'!$C$3,0)+60*ROUND(30*'РАСХОДЫ'!$C$3,0)+5000+5000+(IF(30<=50,8000,IF(30<=75,8000*1.2,8000*1.4)))+2500+4000+(2500*0.7+2500*0.3*30/70)+(IF(30<=50,3000,3000*2))+500+3000+5000+2000)+(IF('РАСХОДЫ'!$C$4="Да",0,((IF(30<=60,13000*0.85,IF(30<=85,13000,13000*1.15)))+3500+55*30*2+30*ROUND(30*'РАСХОДЫ'!$C$3,0)+90*ROUND(30*'РАСХОДЫ'!$C$3,0)+90*ROUND(30*'РАСХОДЫ'!$C$3,0)+75*ROUND(30*'РАСХОДЫ'!$C$3,0)+60*ROUND(30*'РАСХОДЫ'!$C$3,0)+5000+5000+(IF(30<=50,8000,IF(30<=75,8000*1.2,8000*1.4)))+2500+4000+(2500*0.7+2500*0.3*30/70)+(IF(30<=50,3000,3000*2))+500+3000+5000+2000)*0.15))+(((IF(30<=60,13000*0.85,IF(30<=85,13000,13000*1.15)))+3500+55*30*2+30*ROUND(30*'РАСХОДЫ'!$C$3,0)+90*ROUND(30*'РАСХОДЫ'!$C$3,0)+90*ROUND(30*'РАСХОДЫ'!$C$3,0)+75*ROUND(30*'РАСХОДЫ'!$C$3,0)+60*ROUND(30*'РАСХОДЫ'!$C$3,0)+5000+5000+(IF(30<=50,8000,IF(30<=75,8000*1.2,8000*1.4)))+2500+4000+(2500*0.7+2500*0.3*30/70)+(IF(30<=50,3000,3000*2))+500+3000+5000+2000)*0.1))-0.04*((ROUND(30*'ДОХОДЫ'!$C$2*(1-'РАСХОДЫ'!$C$3),0))*('ДОХОДЫ'!$C$3*290+(1-'ДОХОДЫ'!$C$3)*377)+(ROUND(30*'ДОХОДЫ'!$C$2*'РАСХОДЫ'!$C$3,0))*('ДОХОДЫ'!$C$3*590+(1-'ДОХОДЫ'!$C$3)*767)+(MAX(ROUND(30*(1-'ДОХОДЫ'!$C$2)*(1-'РАСХОДЫ'!$C$3),0),0))*('ДОХОДЫ'!$C$3*490+(1-'ДОХОДЫ'!$C$3)*637)+(MAX(ROUND(30*(1-'ДОХОДЫ'!$C$2)*'РАСХОДЫ'!$C$3,0)-(1*2+0*4+0*6),0))*('ДОХОДЫ'!$C$3*890+(1-'ДОХОДЫ'!$C$3)*1157)+'ДОХОДЫ'!$C$5*500+'ДОХОДЫ'!$C$6*1500+1*3000+0*8000+0*15000) | D31: =((ROUND(30*'ДОХОДЫ'!$C$2*(1-'РАСХОДЫ'!$C$3),0))*('ДОХОДЫ'!$C$3*290+(1-'ДОХОДЫ'!$C$3)*377)+(ROUND(30*'ДОХОДЫ'!$C$2*'РАСХОДЫ'!$C$3,0))*('ДОХОДЫ'!$C$3*590+(1-'ДОХОДЫ'!$C$3)*767)+(MAX(ROUND(30*(1-'ДОХОДЫ'!$C$2)*(1-'РАСХОДЫ'!$C$3),0),0))*('ДОХОДЫ'!$C$3*490+(1-'ДОХОДЫ'!$C$3)*637)+(MAX(ROUND(30*(1-'ДОХОДЫ'!$C$2)*'РАСХОДЫ'!$C$3,0)-(1*2+1*4+0*6),0))*('ДОХОДЫ'!$C$3*890+(1-'ДОХОДЫ'!$C$3)*1157)+'ДОХОДЫ'!$C$5*500+'ДОХОДЫ'!$C$6*1500+1*3000+1*8000+0*15000)-(((IF(30<=60,13000*0.85,IF(30<=85,13000,13000*1.15)))+3500+55*30*2+30*ROUND(30*'РАСХОДЫ'!$C$3,0)+90*ROUND(30*'РАСХОДЫ'!$C$3,0)+90*ROUND(30*'РАСХОДЫ'!$C$3,0)+75*ROUND(30*'РАСХОДЫ'!$C$3,0)+60*ROUND(30*'РАСХОДЫ'!$C$3,0)+5000+5000+(IF(30<=50,8000,IF(30<=75,8000*1.2,8000*1.4)))+2500+4000+(2500*0.7+2500*0.3*30/70)+(IF(30<=50,3000,3000*2))+500+3000+5000+2000)+(IF('РАСХОДЫ'!$C$4="Да",0,((IF(30<=60,13000*0.85,IF(30<=85,13000,13000*1.15)))+3500+55*30*2+30*ROUND(30*'РАСХОДЫ'!$C$3,0)+90*ROUND(30*'РАСХОДЫ'!$C$3,0)+90*ROUND(30*'РАСХОДЫ'!$C$3,0)+75*ROUND(30*'РАСХОДЫ'!$C$3,0)+60*ROUND(30*'РАСХОДЫ'!$C$3,0)+5000+5000+(IF(30<=50,8000,IF(30<=75,8000*1.2,8000*1.4)))+2500+4000+(2500*0.7+2500*0.3*30/70)+(IF(30<=50,3000,3000*2))+500+3000+5000+2000)*0.15))+(((IF(30<=60,13000*0.85,IF(30<=85,13000,13000*1.15)))+3500+55*30*2+30*ROUND(30*'РАСХОДЫ'!$C$3,0)+90*ROUND(30*'РАСХОДЫ'!$C$3,0)+90*ROUND(30*'РАСХОДЫ'!$C$3,0)+75*ROUND(30*'РАСХОДЫ'!$C$3,0)+60*ROUND(30*'РАСХОДЫ'!$C$3,0)+5000+5000+(IF(30<=50,8000,IF(30<=75,8000*1.2,8000*1.4)))+2500+4000+(2500*0.7+2500*0.3*30/70)+(IF(30<=50,3000,3000*2))+500+3000+5000+2000)*0.1))-0.04*((ROUND(30*'ДОХОДЫ'!$C$2*(1-'РАСХОДЫ'!$C$3),0))*('ДОХОДЫ'!$C$3*290+(1-'ДОХОДЫ'!$C$3)*377)+(ROUND(30*'ДОХОДЫ'!$C$2*'РАСХОДЫ'!$C$3,0))*('ДОХОДЫ'!$C$3*590+(1-'ДОХОДЫ'!$C$3)*767)+(MAX(ROUND(30*(1-'ДОХОДЫ'!$C$2)*(1-'РАСХОДЫ'!$C$3),0),0))*('ДОХОДЫ'!$C$3*490+(1-'ДОХОДЫ'!$C$3)*637)+(MAX(ROUND(30*(1-'ДОХОДЫ'!$C$2)*'РАСХОДЫ'!$C$3,0)-(1*2+1*4+0*6),0))*('ДОХОДЫ'!$C$3*890+(1-'ДОХОДЫ'!$C$3)*1157)+'ДОХОДЫ'!$C$5*500+'ДОХОДЫ'!$C$6*1500+1*3000+1*8000+0*15000) | E31: =((ROUND(30*'ДОХОДЫ'!$C$2*(1-'РАСХОДЫ'!$C$3),0))*('ДОХОДЫ'!$C$3*290+(1-'ДОХОДЫ'!$C$3)*377)+(ROUND(30*'ДОХОДЫ'!$C$2*'РАСХОДЫ'!$C$3,0))*('ДОХОДЫ'!$C$3*590+(1-'ДОХОДЫ'!$C$3)*767)+(MAX(ROUND(30*(1-'ДОХОДЫ'!$C$2)*(1-'РАСХОДЫ'!$C$3),0),0))*('ДОХОДЫ'!$C$3*490+(1-'ДОХОДЫ'!$C$3)*637)+(MAX(ROUND(30*(1-'ДОХОДЫ'!$C$2)*'РАСХОДЫ'!$C$3,0)-(0*2+1*4+1*6),0))*('ДОХОДЫ'!$C$3*890+(1-'ДОХОДЫ'!$C$3)*1157)+'ДОХОДЫ'!$C$5*500+'ДОХОДЫ'!$C$6*1500+0*3000+1*8000+1*15000)-(((IF(30<=60,13000*0.85,IF(30<=85,13000,13000*1.15)))+3500+55*30*2+30*ROUND(30*'РАСХОДЫ'!$C$3,0)+90*ROUND(30*'РАСХОДЫ'!$C$3,0)+90*ROUND(30*'РАСХОДЫ'!$C$3,0)+75*ROUND(30*'РАСХОДЫ'!$C$3,0)+60*ROUND(30*'РАСХОДЫ'!$C$3,0)+5000+5000+(IF(30<=50,8000,IF(30<=75,8000*1.2,8000*1.4)))+2500+4000+(2500*0.7+2500*0.3*30/70)+(IF(30<=50,3000,3000*2))+500+3000+5000+2000)+(IF('РАСХОДЫ'!$C$4="Да",0,((IF(30<=60,13000*0.85,IF(30<=85,13000,13000*1.15)))+3500+55*30*2+30*ROUND(30*'РАСХОДЫ'!$C$3,0)+90*ROUND(30*'РАСХОДЫ'!$C$3,0)+90*ROUND(30*'РАСХОДЫ'!$C$3,0)+75*ROUND(30*'РАСХОДЫ'!$C$3,0)+60*ROUND(30*'РАСХОДЫ'!$C$3,0)+5000+5000+(IF(30<=50,8000,IF(30<=75,8000*1.2,8000*1.4)))+2500+4000+(2500*0.7+2500*0.3*30/70)+(IF(30<=50,3000,3000*2))+500+3000+5000+2000)*0.15))+(((IF(30<=60,13000*0.85,IF(30<=85,13000,13000*1.15)))+3500+55*30*2+30*ROUND(30*'РАСХОДЫ'!$C$3,0)+90*ROUND(30*'РАСХОДЫ'!$C$3,0)+90*ROUND(30*'РАСХОДЫ'!$C$3,0)+75*ROUND(30*'РАСХОДЫ'!$C$3,0)+60*ROUND(30*'РАСХОДЫ'!$C$3,0)+5000+5000+(IF(30<=50,8000,IF(30<=75,8000*1.2,8000*1.4)))+2500+4000+(2500*0.7+2500*0.3*30/70)+(IF(30<=50,3000,3000*2))+500+3000+5000+2000)*0.1))-0.04*((ROUND(30*'ДОХОДЫ'!$C$2*(1-'РАСХОДЫ'!$C$3),0))*('ДОХОДЫ'!$C$3*290+(1-'ДОХОДЫ'!$C$3)*377)+(ROUND(30*'ДОХОДЫ'!$C$2*'РАСХОДЫ'!$C$3,0))*('ДОХОДЫ'!$C$3*590+(1-'ДОХОДЫ'!$C$3)*767)+(MAX(ROUND(30*(1-'ДОХОДЫ'!$C$2)*(1-'РАСХОДЫ'!$C$3),0),0))*('ДОХОДЫ'!$C$3*490+(1-'ДОХОДЫ'!$C$3)*637)+(MAX(ROUND(30*(1-'ДОХОДЫ'!$C$2)*'РАСХОДЫ'!$C$3,0)-(0*2+1*4+1*6),0))*('ДОХОДЫ'!$C$3*890+(1-'ДОХОДЫ'!$C$3)*1157)+'ДОХОДЫ'!$C$5*500+'ДОХОДЫ'!$C$6*1500+0*3000+1*8000+1*15000) | F31: =((ROUND(30*'ДОХОДЫ'!$C$2*(1-'РАСХОДЫ'!$C$3),0))*('ДОХОДЫ'!$C$3*290+(1-'ДОХОДЫ'!$C$3)*377)+(ROUND(30*'ДОХОДЫ'!$C$2*'РАСХОДЫ'!$C$3,0))*('ДОХОДЫ'!$C$3*590+(1-'ДОХОДЫ'!$C$3)*767)+(MAX(ROUND(30*(1-'ДОХОДЫ'!$C$2)*(1-'РАСХОДЫ'!$C$3),0),0))*('ДОХОДЫ'!$C$3*490+(1-'ДОХОДЫ'!$C$3)*637)+(MAX(ROUND(30*(1-'ДОХОДЫ'!$C$2)*'РАСХОДЫ'!$C$3,0)-(1*2+1*4+1*6),0))*('ДОХОДЫ'!$C$3*890+(1-'ДОХОДЫ'!$C$3)*1157)+'ДОХОДЫ'!$C$5*500+'ДОХОДЫ'!$C$6*1500+1*3000+1*8000+1*15000)-(((IF(30<=60,13000*0.85,IF(30<=85,13000,13000*1.15)))+3500+55*30*2+30*ROUND(30*'РАСХОДЫ'!$C$3,0)+90*ROUND(30*'РАСХОДЫ'!$C$3,0)+90*ROUND(30*'РАСХОДЫ'!$C$3,0)+75*ROUND(30*'РАСХОДЫ'!$C$3,0)+60*ROUND(30*'РАСХОДЫ'!$C$3,0)+5000+5000+(IF(30<=50,8000,IF(30<=75,8000*1.2,8000*1.4)))+2500+4000+(2500*0.7+2500*0.3*30/70)+(IF(30<=50,3000,3000*2))+500+3000+5000+2000)+(IF('РАСХОДЫ'!$C$4="Да",0,((IF(30<=60,13000*0.85,IF(30<=85,13000,13000*1.15)))+3500+55*30*2+30*ROUND(30*'РАСХОДЫ'!$C$3,0)+90*ROUND(30*'РАСХОДЫ'!$C$3,0)+90*ROUND(30*'РАСХОДЫ'!$C$3,0)+75*ROUND(30*'РАСХОДЫ'!$C$3,0)+60*ROUND(30*'РАСХОДЫ'!$C$3,0)+5000+5000+(IF(30<=50,8000,IF(30<=75,8000*1.2,8000*1.4)))+2500+4000+(2500*0.7+2500*0.3*30/70)+(IF(30<=50,3000,3000*2))+500+3000+5000+2000)*0.15))+(((IF(30<=60,13000*0.85,IF(30<=85,13000,13000*1.15)))+3500+55*30*2+30*ROUND(30*'РАСХОДЫ'!$C$3,0)+90*ROUND(30*'РАСХОДЫ'!$C$3,0)+90*ROUND(30*'РАСХОДЫ'!$C$3,0)+75*ROUND(30*'РАСХОДЫ'!$C$3,0)+60*ROUND(30*'РАСХОДЫ'!$C$3,0)+5000+5000+(IF(30<=50,8000,IF(30<=75,8000*1.2,8000*1.4)))+2500+4000+(2500*0.7+2500*0.3*30/70)+(IF(30<=50,3000,3000*2))+500+3000+5000+2000)*0.1))-0.04*((ROUND(30*'ДОХОДЫ'!$C$2*(1-'РАСХОДЫ'!$C$3),0))*('ДОХОДЫ'!$C$3*290+(1-'ДОХОДЫ'!$C$3)*377)+(ROUND(30*'ДОХОДЫ'!$C$2*'РАСХОДЫ'!$C$3,0))*('ДОХОДЫ'!$C$3*590+(1-'ДОХОДЫ'!$C$3)*767)+(MAX(ROUND(30*(1-'ДОХОДЫ'!$C$2)*(1-'РАСХОДЫ'!$C$3),0),0))*('ДОХОДЫ'!$C$3*490+(1-'ДОХОДЫ'!$C$3)*637)+(MAX(ROUND(30*(1-'ДОХОДЫ'!$C$2)*'РАСХОДЫ'!$C$3,0)-(1*2+1*4+1*6),0))*('ДОХОДЫ'!$C$3*890+(1-'ДОХОДЫ'!$C$3)*1157)+'ДОХОДЫ'!$C$5*500+'ДОХОДЫ'!$C$6*1500+1*3000+1*8000+1*15000)
